Workbook

Sheet 조사양식
A1: NewSerials | B1: NewNo. | C1: 사업장명 | D1: 자재코드 | E1: 자재명 | F1: 내자/외자 | G1: 현재 취급 유무 (O/X 선택) | H1: 공정명 | I1: 사용부서명 | J1: 제조업체명 | K1: 공급업체명 | L1: 공급업체코드 | M1: 자재용도 | N1: 자재용도(세부) | O1: 자재구분 | P1: 성상 | Q1: 국내 구매량(kg) 2022 | R1: 국내 구매량(kg) 2022 계획 | S1: 수입량(kg) 2022 | T1: 수입량(kg) 2022 계획 | U1: 사용량(kg) 2023 계획 | V1: 사용량(kg) | W1: (*자동생성)MSDS 명 (사용부서_자재명_제조업체명) | X1: 구성성분 명 | Y1: 함량(wt%) 평균값 | Z1: 함량 최소값 (수치) | AA1: 함량 최대값 (수치) | AB1: 함량(W%) | AC1: 성분용도 | AD1: 대외비여부 | AE1: MSDS여부 | AF1: GHS여부 | AG1: 비고 | AH1: CAS No. | AI1: 물질량(kg) | AJ1: EC No. | AK1: UN No. | AL1: 물질명 | AM1: MSDS 내 CAS No. (수화물) | AN1: 신규물질 | AO1: 등록대상기존화학물질 | AP1: 기존화학물질번호 | AQ1: 유독물질 고시번호 | AR1: 제품_유독물질 | AS1: 금지물질 고시번호 | AT1: 제품_금지물질 | AU1: 제한물질 고시번호 | AV1: 제품_제한물질 | AW1: 사고대비물질명 | AX1: 제품 사고대비물질 | AY1: 사고대비물질 저장(kg) | AZ1: 사고대비물질 취급량 기준(kg/yr) | BA1: 사고대비물질_호흡보호구 | BB1: 사고대비물질_보호복 | BC1: 사고대비물질_보호장갑 | BD1: 배출량조사 I(1ton) | BE1: 배출량조사 II(10ton) | BF1: 산안법_금지물질 | BG1: 산안법_허가물질 제품 | BH1: 산안법_특별관리물질 제품 | BI1: 산안법_관리대상유해물질 제품 | BJ1: 산안법_허용기준이하물질 제품 | BK1: 산안법_허용기준이하물질 농도(TWA_mg/m3) | BL1: 산안법_노출기준설정물질 제품 | BM1: 산안법_노출기준설정물질(TWA_ppm) | BN1: 산안법_노출기준설정물질(TWA_mg/m3) | BO1: 산안법_노출기준설정물질(STEL_ppm) | BP1: 산안법_노출기준설정물질(STEL_mg/m3) | BQ1: 산안법_노출기준설정물질(Ceiling_ppm) | BR1: 산안법_노출기준설정물질(Ceiling_mg/m3) | BS1: 산안법_노출기준설정물질(skin notation) | BT1: 산안법_작업환경측정대상유해인자 | BU1: 산안법_특수건강진단대상유해인자 | BV1: 고용노동부고시_발암성물질 | BW1: 고용노동부고시_생식세포변이원성물질 | BX1: 고용노동부고시_생식독성물질 | BY1: 위험물안전관리법_위험물분류 | BZ1: 고압가스안전관리법_독성가스 | CA1: 고압가스안전관리법_가연성가스 | CB1: 고압가스안전관리법_특수고압가스 | CC1: 고압가스안전관리법_특정고압가스 | CD1: 화관법_개별화학물질_취급기준(별표1)
A2: 1 | C2: 삼화당피앤티 | E2: ho 402 | F2: 내자 | G2: O | H2: 윤전 | I2: 인쇄 | J2: ㈜화승인더스트리 | K2: ㈜화승인더스트리 | M2: 원부자재 | N2: 옵셋 윤전 인쇄용 | O2: 혼합물 | P2: 고체 | Q2: 200 | R2: 200 | U2: 200 | V2: 200 | W2: =표1[[#This Row],[자재코드]]&"_"&표1[[#This Row],[자재명]]&"_"&표1[[#This Row],[공급업체명]] -> _ho 402_㈜화승인더스트리 | X2: 실리카 수화물 | AB2: 0.9 | AC2: 코팅제 | AD2: X | AE2: O | AF2: O | AH2: 112926-00-8 | AI2: =IFERROR(표1[[#This Row],[사용량(kg)]]*표1[[#This Row],[함량(W%)]]/100,"") -> 1.8 | AR2: =IFERROR(IF(표1[[#This Row],[함량(W%)]]>=VLOOKUP(표1[[#This Row],[CAS No.]],[1]규제DB_유해법_유독물!B:F,5,FALSE),"유독물질 제품",""),"") | AS2: =IFERROR(VLOOKUP(표1[[#This Row],[CAS No.]],[1]규제DB_유해법_금지물질!B:G,3,FALSE),"") | AT2: =IFERROR(VLOOKUP(표1[[#This Row],[CAS No.]],[1]규제DB_유해법_금지물질!B:G,4,FALSE)&" 인지 확인하세요","") | AU2: =IFERROR(VLOOKUP(표1[[#This Row],[CAS No.]],[1]규제DB_유해법_제한물질!B:G,3,FALSE),"") | AV2: =IFERROR(IF(표1[[#This Row],[함량(W%)]]>=VLOOKUP(표1[[#This Row],[CAS No.]],[1]규제DB_유해법_제한물질!$B:$G,5,FALSE),"제한 제품",""),"") | BA2: =IFERROR(IF(표1[[#This Row],[함량(W%)]]>=VLOOKUP(표1[[#This Row],[CAS No.]],[1]규제DB_유해법_사고대비물질!$B:$J,4,FALSE),VLOOKUP(표1[[#This Row],[CAS No.]],[1]규제DB_유해법_사고대비물질!$B$2:$J$70,7,FALSE),""),"") | BB2: =IFERROR(IF(표1[[#This Row],[함량(W%)]]>=VLOOKUP(표1[[#This Row],[CAS No.]],[1]규제DB_유해법_사고대비물질!$B:$J,4,FALSE),VLOOKUP(표1[[#This Row],[CAS No.]],[1]규제DB_유해법_사고대비물질!$B$2:$J$70,8,FALSE),""),"") | BC2: =IFERROR(IF(표1[[#This Row],[함량(W%)]]>=VLOOKUP(표1[[#This Row],[CAS No.]],[1]규제DB_유해법_사고대비물질!$B:$J,4,FALSE),VLOOKUP(표1[[#This Row],[CAS No.]],[1]규제DB_유해법_사고대비물질!$B$2:$J$70,9,FALSE),""),"") | BD2: =IFERROR(IF(표1[[#This Row],[함량(W%)]]>=VLOOKUP(표1[[#This Row],[CAS No.]],'[1]규제DB_유해법_배출량조사 I'!$B:$D,3,FALSE),IF(VLOOKUP(표1[[#This Row],[CAS No.]],[1]기초자료!$A:$C,3,FALSE)>=1000,"배출량조사 I 물질",""),""),"") | BE2: =IFERROR(IF(표1[[#This Row],[함량(W%)]]>=VLOOKUP(표1[[#This Row],[CAS No.]],'[1]규제DB_유해법_배출량조사 II'!B:D,3,FALSE),IF(VLOOKUP(표1[[#This Row],[CAS No.]],[1]기초자료!$A:$C,3,FALSE)>=10000,"배출량조사 II 물질",""),""),"") | BF2: =IFERROR(IF(표1[[#This Row],[함량(W%)]]>=VLOOKUP(표1[[#This Row],[CAS No.]],[1]규제DB_산안법_금지물질!$B:$E,4,FALSE), VLOOKUP(표1[[#This Row],[CAS No.]],[1]규제DB_산안법_금지물질!$B:$E,2,FALSE)&" : "&VLOOKUP(표1[[#This Row],[CAS No.]],[1]규제DB_산안법_금지물질!$B:$E,3,FALSE)&" 인지 확인하세요",""),"") | BG2: =IFERROR(IF(표1[[#This Row],[함량(W%)]]>=VLOOKUP(표1[[#This Row],[CAS No.]],[1]규제DB_산안법_허가물질!$B:$E,4,FALSE), "제품 허가물질",""),"") | BH2: =IFERROR(IF(표1[[#This Row],[함량(W%)]]>=VLOOKUP(표1[[#This Row],[CAS No.]], [1]규제DB_산안법_특별관리물질!$B:$E,4,FALSE), "제품 특별관리물질",""),"") | BI2: =IFERROR(IF(표1[[#This Row],[함량(W%)]]>=VLOOKUP(표1[[#This Row],[CAS No.]], [1]규제DB_산안법_관리대상유해물질!$B:$E,4,FALSE), "제품 관리대상유해물질",""),"") | BJ2: =IFERROR(IF(표1[[#This Row],[CAS No.]]=VLOOKUP(표1[[#This Row],[CAS No.]], [1]규제DB_산안법_허용기준이하물질!$B:$D,1,FALSE),"제품 허용기준이하물질",""),"") | BK2: =IFERROR(VLOOKUP(표1[[#This Row],[CAS No.]], [1]규제DB_산안법_허용기준이하물질!$B:$D,3,FALSE),"") | BQ2: =IFERROR(VLOOKUP(표1[[#This Row],[CAS No.]], [1]규제DB_산안법_노출기준설정물질!$B:$K,8,FALSE),"") | BR2: =IFERROR(VLOOKUP(표1[[#This Row],[CAS No.]], [1]규제DB_산안법_노출기준설정물질!$B:$K,9,FALSE),"") | BS2: =IFERROR(VLOOKUP(표1[[#This Row],[CAS No.]], [1]규제DB_산안법_노출기준설정물질!$B:$K,10,FALSE),"") | BV2: =IFERROR(IF(VLOOKUP(표1[[#This Row],[CAS No.]],[1]규제DB_고용노동부고시_CMR!$B:$J,3,FALSE)="구분1A", IF(표1[[#This Row],[함량(W%)]]>=VLOOKUP(표1[[#This Row],[CAS No.]],[1]규제DB_고용노동부고시_CMR!$B:$J,4,FALSE),"제품 발암성물질",""), IF(VLOOKUP(표1[[#This Row],[CAS No.]],[1]규제DB_고용노동부고시_CMR!$B:$J,3,FALSE)="구분1B", IF(표1[[#This Row],[함량(W%)]]>=VLOOKUP(표1[[#This Row],[CAS No.]],[1]규제DB_고용노동부고시_CMR!$B:$J,4,FALSE),"제품 발암성물질",""), IF(VLOOKUP(표1[[#This Row],[CAS No.]],[1]규제DB_고용노동부고시_CMR!$B:$J,3,FALSE)="구분2", IF(표1[[#This Row],[함량(W%)]]>=VLOOKUP(표1[[#This Row],[CAS No.]],[1]규제DB_고용노동부고시_CMR!$B:$J,4,FALSE),"제품 발암성물질",""),""))),"") | BW2: =IFERROR(IF(VLOOKUP(표1[[#This Row],[CAS No.]],[1]규제DB_고용노동부고시_CMR!$B:$J,5,FALSE)="구분1A", IF(표1[[#This Row],[함량(W%)]]>=VLOOKUP(표1[[#This Row],[CAS No.]],[1]규제DB_고용노동부고시_CMR!$B:$J,6,FALSE),"제품 생식세포변이원성물질",""), IF(VLOOKUP(표1[[#This Row],[CAS No.]],[1]규제DB_고용노동부고시_CMR!$B:$J,5,FALSE)="구분1B", IF(표1[[#This Row],[함량(W%)]]>=VLOOKUP(표1[[#This Row],[CAS No.]],[1]규제DB_고용노동부고시_CMR!$B:$J,6,FALSE),"제품 생식세포변이원성물질",""), IF(VLOOKUP(표1[[#This Row],[CAS No.]],[1]규제DB_고용노동부고시_CMR!$B:$J,5,FALSE)="구분2", IF(표1[[#This Row],[함량(W%)]]>=VLOOKUP(표1[[#This Row],[CAS No.]],[1]규제DB_고용노동부고시_CMR!$B:$J,6,FALSE),"제품 생식세포변이원성물질",""),""))),"") | BX2: =IFERROR(IF(VLOOKUP(표1[[#This Row],[CAS No.]],[1]규제DB_고용노동부고시_CMR!$B:$J,7,FALSE)="구분1A", IF(표1[[#This Row],[함량(W%)]]>=VLOOKUP(표1[[#This Row],[CAS No.]],[1]규제DB_고용노동부고시_CMR!$B:$J,8,FALSE),"제품 생식독성물질",""), IF(VLOOKUP(표1[[#This Row],[CAS No.]],[1]규제DB_고용노동부고시_CMR!$B:$J,7,FALSE)="구분1B", IF(표1[[#This Row],[함량(W%)]]>=VLOOKUP(표1[[#This Row],[CAS No.]],[1]규제DB_고용노동부고시_CMR!$B:$J,8,FALSE),"제품 생식독성물질",""), IF(VLOOKUP(표1[[#This Row],[CAS No.]],[1]규제DB_고용노동부고시_CMR!$B:$J,7,FALSE)="구분2", IF(표1[[#This Row],[함량(W%)]]>=VLOOKUP(표1[[#This Row],[CAS No.]],[1]규제DB_고용노동부고시_CMR!$B:$J,8,FALSE),"제품 생식독성물질",""),""))),"") | BY2: =IFERROR(VLOOKUP(표1[[#This Row],[CAS No.]],[1]규제DB_위험물안전관리법_위험물!$B:$F,3,FALSE),"") | BZ2: =IFERROR(IF(표1[[#This Row],[CAS No.]]=VLOOKUP(표1[[#This Row],[CAS No.]],[1]규제DB_고압법_독성가스!$B:$D,1,FALSE),"독성가스",""),"") | CA2: =IFERROR(IF(표1[[#This Row],[CAS No.]]=VLOOKUP(표1[[#This Row],[CAS No.]],[1]규제DB_고압법_가연성가스!$B:$D,1,FALSE),"가연성가스",""),"") | CB2: =IFERROR(IF(표1[[#This Row],[CAS No.]]=VLOOKUP(표1[[#This Row],[CAS No.]],[1]규제DB_고압법_특수고압가스!$B:$D,1,FALSE),"특수고압가스",""),"") | CC2: =IFERROR(IF(표1[[#This Row],[CAS No.]]=VLOOKUP(표1[[#This Row],[CAS No.]],[1]규제DB_고압법_특정고압가스!$B:$D,1,FALSE),"특정고압가스",""),"") | CD2: =IFERROR(IF(표1[[#This Row],[함량(W%)]]>=VLOOKUP(표1[[#This Row],[CAS No.]],[1]규제DB_화관법_개별취급기준!$B:$G,5,FALSE),VLOOKUP(표1[[#This Row],[CAS No.]],[1]규제DB_화관법_개별취급기준!$B:$G,6,FALSE),""),"")
A3: 2 | C3: 삼화당피앤티 | E3: ho 402 | F3: 내자 | G3: O | H3: 윤전 | I3: 인쇄 | J3: ㈜화승인더스트리 | K3: ㈜화승인더스트리 | M3: 원부자재 | N3: 옵셋 윤전 인쇄용 | O3: 혼합물 | P3: 고체 | Q3: 200 | R3: 200 | U3: 200 | V3: 200 | W3: =표1[[#This Row],[자재코드]]&"_"&표1[[#This Row],[자재명]]&"_"&표1[[#This Row],[공급업체명]] -> _ho 402_㈜화승인더스트리 | X3: 폴리에틸렌(POLYETHYLENE) | AB3: 9 | AC3: 코팅제 | AD3: X | AE3: O | AF3: O | AH3: 9002-88-4 | AI3: =IFERROR(표1[[#This Row],[사용량(kg)]]*표1[[#This Row],[함량(W%)]]/100,"") -> 18 | AR3: =IFERROR(IF(표1[[#This Row],[함량(W%)]]>=VLOOKUP(표1[[#This Row],[CAS No.]],[1]규제DB_유해법_유독물!B:F,5,FALSE),"유독물질 제품",""),"") | AS3: =IFERROR(VLOOKUP(표1[[#This Row],[CAS No.]],[1]규제DB_유해법_금지물질!B:G,3,FALSE),"") | AT3: =IFERROR(VLOOKUP(표1[[#This Row],[CAS No.]],[1]규제DB_유해법_금지물질!B:G,4,FALSE)&" 인지 확인하세요","") | AU3: =IFERROR(VLOOKUP(표1[[#This Row],[CAS No.]],[1]규제DB_유해법_제한물질!B:G,3,FALSE),"") | AV3: =IFERROR(IF(표1[[#This Row],[함량(W%)]]>=VLOOKUP(표1[[#This Row],[CAS No.]],[1]규제DB_유해법_제한물질!$B:$G,5,FALSE),"제한 제품",""),"") | BA3: =IFERROR(IF(표1[[#This Row],[함량(W%)]]>=VLOOKUP(표1[[#This Row],[CAS No.]],[1]규제DB_유해법_사고대비물질!$B:$J,4,FALSE),VLOOKUP(표1[[#This Row],[CAS No.]],[1]규제DB_유해법_사고대비물질!$B$2:$J$70,7,FALSE),""),"") | BB3: =IFERROR(IF(표1[[#This Row],[함량(W%)]]>=VLOOKUP(표1[[#This Row],[CAS No.]],[1]규제DB_유해법_사고대비물질!$B:$J,4,FALSE),VLOOKUP(표1[[#This Row],[CAS No.]],[1]규제DB_유해법_사고대비물질!$B$2:$J$70,8,FALSE),""),"") | BC3: =IFERROR(IF(표1[[#This Row],[함량(W%)]]>=VLOOKUP(표1[[#This Row],[CAS No.]],[1]규제DB_유해법_사고대비물질!$B:$J,4,FALSE),VLOOKUP(표1[[#This Row],[CAS No.]],[1]규제DB_유해법_사고대비물질!$B$2:$J$70,9,FALSE),""),"") | BD3: =IFERROR(IF(표1[[#This Row],[함량(W%)]]>=VLOOKUP(표1[[#This Row],[CAS No.]],'[1]규제DB_유해법_배출량조사 I'!$B:$D,3,FALSE),IF(VLOOKUP(표1[[#This Row],[CAS No.]],[1]기초자료!$A:$C,3,FALSE)>=1000,"배출량조사 I 물질",""),""),"") | BE3: =IFERROR(IF(표1[[#This Row],[함량(W%)]]>=VLOOKUP(표1[[#This Row],[CAS No.]],'[1]규제DB_유해법_배출량조사 II'!B:D,3,FALSE),IF(VLOOKUP(표1[[#This Row],[CAS No.]],[1]기초자료!$A:$C,3,FALSE)>=10000,"배출량조사 II 물질",""),""),"") | BF3: =IFERROR(IF(표1[[#This Row],[함량(W%)]]>=VLOOKUP(표1[[#This Row],[CAS No.]],[1]규제DB_산안법_금지물질!$B:$E,4,FALSE), VLOOKUP(표1[[#This Row],[CAS No.]],[1]규제DB_산안법_금지물질!$B:$E,2,FALSE)&" : "&VLOOKUP(표1[[#This Row],[CAS No.]],[1]규제DB_산안법_금지물질!$B:$E,3,FALSE)&" 인지 확인하세요",""),"") | BG3: =IFERROR(IF(표1[[#This Row],[함량(W%)]]>=VLOOKUP(표1[[#This Row],[CAS No.]],[1]규제DB_산안법_허가물질!$B:$E,4,FALSE), "제품 허가물질",""),"") | BH3: =IFERROR(IF(표1[[#This Row],[함량(W%)]]>=VLOOKUP(표1[[#This Row],[CAS No.]], [1]규제DB_산안법_특별관리물질!$B:$E,4,FALSE), "제품 특별관리물질",""),"") | BI3: =IFERROR(IF(표1[[#This Row],[함량(W%)]]>=VLOOKUP(표1[[#This Row],[CAS No.]], [1]규제DB_산안법_관리대상유해물질!$B:$E,4,FALSE), "제품 관리대상유해물질",""),"") | BJ3: =IFERROR(IF(표1[[#This Row],[CAS No.]]=VLOOKUP(표1[[#This Row],[CAS No.]], [1]규제DB_산안법_허용기준이하물질!$B:$D,1,FALSE),"제품 허용기준이하물질",""),"") | BK3: =IFERROR(VLOOKUP(표1[[#This Row],[CAS No.]], [1]규제DB_산안법_허용기준이하물질!$B:$D,3,FALSE),"") | BQ3: =IFERROR(VLOOKUP(표1[[#This Row],[CAS No.]], [1]규제DB_산안법_노출기준설정물질!$B:$K,8,FALSE),"") | BR3: =IFERROR(VLOOKUP(표1[[#This Row],[CAS No.]], [1]규제DB_산안법_노출기준설정물질!$B:$K,9,FALSE),"") | BS3: =IFERROR(VLOOKUP(표1[[#This Row],[CAS No.]], [1]규제DB_산안법_노출기준설정물질!$B:$K,10,FALSE),"") | BV3: =IFERROR(IF(VLOOKUP(표1[[#This Row],[CAS No.]],[1]규제DB_고용노동부고시_CMR!$B:$J,3,FALSE)="구분1A", IF(표1[[#This Row],[함량(W%)]]>=VLOOKUP(표1[[#This Row],[CAS No.]],[1]규제DB_고용노동부고시_CMR!$B:$J,4,FALSE),"제품 발암성물질",""), IF(VLOOKUP(표1[[#This Row],[CAS No.]],[1]규제DB_고용노동부고시_CMR!$B:$J,3,FALSE)="구분1B", IF(표1[[#This Row],[함량(W%)]]>=VLOOKUP(표1[[#This Row],[CAS No.]],[1]규제DB_고용노동부고시_CMR!$B:$J,4,FALSE),"제품 발암성물질",""), IF(VLOOKUP(표1[[#This Row],[CAS No.]],[1]규제DB_고용노동부고시_CMR!$B:$J,3,FALSE)="구분2", IF(표1[[#This Row],[함량(W%)]]>=VLOOKUP(표1[[#This Row],[CAS No.]],[1]규제DB_고용노동부고시_CMR!$B:$J,4,FALSE),"제품 발암성물질",""),""))),"") | BW3: =IFERROR(IF(VLOOKUP(표1[[#This Row],[CAS No.]],[1]규제DB_고용노동부고시_CMR!$B:$J,5,FALSE)="구분1A", IF(표1[[#This Row],[함량(W%)]]>=VLOOKUP(표1[[#This Row],[CAS No.]],[1]규제DB_고용노동부고시_CMR!$B:$J,6,FALSE),"제품 생식세포변이원성물질",""), IF(VLOOKUP(표1[[#This Row],[CAS No.]],[1]규제DB_고용노동부고시_CMR!$B:$J,5,FALSE)="구분1B", IF(표1[[#This Row],[함량(W%)]]>=VLOOKUP(표1[[#This Row],[CAS No.]],[1]규제DB_고용노동부고시_CMR!$B:$J,6,FALSE),"제품 생식세포변이원성물질",""), IF(VLOOKUP(표1[[#This Row],[CAS No.]],[1]규제DB_고용노동부고시_CMR!$B:$J,5,FALSE)="구분2", IF(표1[[#This Row],[함량(W%)]]>=VLOOKUP(표1[[#This Row],[CAS No.]],[1]규제DB_고용노동부고시_CMR!$B:$J,6,FALSE),"제품 생식세포변이원성물질",""),""))),"") | BX3: =IFERROR(IF(VLOOKUP(표1[[#This Row],[CAS No.]],[1]규제DB_고용노동부고시_CMR!$B:$J,7,FALSE)="구분1A", IF(표1[[#This Row],[함량(W%)]]>=VLOOKUP(표1[[#This Row],[CAS No.]],[1]규제DB_고용노동부고시_CMR!$B:$J,8,FALSE),"제품 생식독성물질",""), IF(VLOOKUP(표1[[#This Row],[CAS No.]],[1]규제DB_고용노동부고시_CMR!$B:$J,7,FALSE)="구분1B", IF(표1[[#This Row],[함량(W%)]]>=VLOOKUP(표1[[#This Row],[CAS No.]],[1]규제DB_고용노동부고시_CMR!$B:$J,8,FALSE),"제품 생식독성물질",""), IF(VLOOKUP(표1[[#This Row],[CAS No.]],[1]규제DB_고용노동부고시_CMR!$B:$J,7,FALSE)="구분2", IF(표1[[#This Row],[함량(W%)]]>=VLOOKUP(표1[[#This Row],[CAS No.]],[1]규제DB_고용노동부고시_CMR!$B:$J,8,FALSE),"제품 생식독성물질",""),""))),"") | BY3: =IFERROR(VLOOKUP(표1[[#This Row],[CAS No.]],[1]규제DB_위험물안전관리법_위험물!$B:$F,3,FALSE),"") | BZ3: =IFERROR(IF(표1[[#This Row],[CAS No.]]=VLOOKUP(표1[[#This Row],[CAS No.]],[1]규제DB_고압법_독성가스!$B:$D,1,FALSE),"독성가스",""),"") | CA3: =IFERROR(IF(표1[[#This Row],[CAS No.]]=VLOOKUP(표1[[#This Row],[CAS No.]],[1]규제DB_고압법_가연성가스!$B:$D,1,FALSE),"가연성가스",""),"") | CB3: =IFERROR(IF(표1[[#This Row],[CAS No.]]=VLOOKUP(표1[[#This Row],[CAS No.]],[1]규제DB_고압법_특수고압가스!$B:$D,1,FALSE),"특수고압가스",""),"") | CC3: =IFERROR(IF(표1[[#This Row],[CAS No.]]=VLOOKUP(표1[[#This Row],[CAS No.]],[1]규제DB_고압법_특정고압가스!$B:$D,1,FALSE),"특정고압가스",""),"") | CD3: =IFERROR(IF(표1[[#This Row],[함량(W%)]]>=VLOOKUP(표1[[#This Row],[CAS No.]],[1]규제DB_화관법_개별취급기준!$B:$G,5,FALSE),VLOOKUP(표1[[#This Row],[CAS No.]],[1]규제DB_화관법_개별취급기준!$B:$G,6,FALSE),""),"")
A4: 3 | C4: 삼화당피앤티 | E4: ho 402 | F4: 내자 | G4: O | H4: 윤전 | I4: 인쇄 | J4: ㈜화승인더스트리 | K4: ㈜화승인더스트리 | M4: 원부자재 | N4: 옵셋 윤전 인쇄용 | O4: 혼합물 | P4: 고체 | Q4: 200 | R4: 200 | U4: 200 | V4: 200 | W4: =표1[[#This Row],[자재코드]]&"_"&표1[[#This Row],[자재명]]&"_"&표1[[#This Row],[공급업체명]] -> _ho 402_㈜화승인더스트리 | X4: 에틸렌-프로필렌 공중합체(ETHYLENE-PROPYLENE COPOLYMER) | AB4: 10 | AC4: 코팅제 | AD4: X | AE4: O | AF4: O | AH4: 9010-79-1 | AI4: =IFERROR(표1[[#This Row],[사용량(kg)]]*표1[[#This Row],[함량(W%)]]/100,"") -> 20 | AR4: =IFERROR(IF(표1[[#This Row],[함량(W%)]]>=VLOOKUP(표1[[#This Row],[CAS No.]],[1]규제DB_유해법_유독물!B:F,5,FALSE),"유독물질 제품",""),"") | AS4: =IFERROR(VLOOKUP(표1[[#This Row],[CAS No.]],[1]규제DB_유해법_금지물질!B:G,3,FALSE),"") | AT4: =IFERROR(VLOOKUP(표1[[#This Row],[CAS No.]],[1]규제DB_유해법_금지물질!B:G,4,FALSE)&" 인지 확인하세요","") | AU4: =IFERROR(VLOOKUP(표1[[#This Row],[CAS No.]],[1]규제DB_유해법_제한물질!B:G,3,FALSE),"") | AV4: =IFERROR(IF(표1[[#This Row],[함량(W%)]]>=VLOOKUP(표1[[#This Row],[CAS No.]],[1]규제DB_유해법_제한물질!$B:$G,5,FALSE),"제한 제품",""),"") | BA4: =IFERROR(IF(표1[[#This Row],[함량(W%)]]>=VLOOKUP(표1[[#This Row],[CAS No.]],[1]규제DB_유해법_사고대비물질!$B:$J,4,FALSE),VLOOKUP(표1[[#This Row],[CAS No.]],[1]규제DB_유해법_사고대비물질!$B$2:$J$70,7,FALSE),""),"") | BB4: =IFERROR(IF(표1[[#This Row],[함량(W%)]]>=VLOOKUP(표1[[#This Row],[CAS No.]],[1]규제DB_유해법_사고대비물질!$B:$J,4,FALSE),VLOOKUP(표1[[#This Row],[CAS No.]],[1]규제DB_유해법_사고대비물질!$B$2:$J$70,8,FALSE),""),"") | BC4: =IFERROR(IF(표1[[#This Row],[함량(W%)]]>=VLOOKUP(표1[[#This Row],[CAS No.]],[1]규제DB_유해법_사고대비물질!$B:$J,4,FALSE),VLOOKUP(표1[[#This Row],[CAS No.]],[1]규제DB_유해법_사고대비물질!$B$2:$J$70,9,FALSE),""),"") | BD4: =IFERROR(IF(표1[[#This Row],[함량(W%)]]>=VLOOKUP(표1[[#This Row],[CAS No.]],'[1]규제DB_유해법_배출량조사 I'!$B:$D,3,FALSE),IF(VLOOKUP(표1[[#This Row],[CAS No.]],[1]기초자료!$A:$C,3,FALSE)>=1000,"배출량조사 I 물질",""),""),"") | BE4: =IFERROR(IF(표1[[#This Row],[함량(W%)]]>=VLOOKUP(표1[[#This Row],[CAS No.]],'[1]규제DB_유해법_배출량조사 II'!B:D,3,FALSE),IF(VLOOKUP(표1[[#This Row],[CAS No.]],[1]기초자료!$A:$C,3,FALSE)>=10000,"배출량조사 II 물질",""),""),"") | BF4: =IFERROR(IF(표1[[#This Row],[함량(W%)]]>=VLOOKUP(표1[[#This Row],[CAS No.]],[1]규제DB_산안법_금지물질!$B:$E,4,FALSE), VLOOKUP(표1[[#This Row],[CAS No.]],[1]규제DB_산안법_금지물질!$B:$E,2,FALSE)&" : "&VLOOKUP(표1[[#This Row],[CAS No.]],[1]규제DB_산안법_금지물질!$B:$E,3,FALSE)&" 인지 확인하세요",""),"") | BG4: =IFERROR(IF(표1[[#This Row],[함량(W%)]]>=VLOOKUP(표1[[#This Row],[CAS No.]],[1]규제DB_산안법_허가물질!$B:$E,4,FALSE), "제품 허가물질",""),"") | BH4: =IFERROR(IF(표1[[#This Row],[함량(W%)]]>=VLOOKUP(표1[[#This Row],[CAS No.]], [1]규제DB_산안법_특별관리물질!$B:$E,4,FALSE), "제품 특별관리물질",""),"") | BI4: =IFERROR(IF(표1[[#This Row],[함량(W%)]]>=VLOOKUP(표1[[#This Row],[CAS No.]], [1]규제DB_산안법_관리대상유해물질!$B:$E,4,FALSE), "제품 관리대상유해물질",""),"") | BJ4: =IFERROR(IF(표1[[#This Row],[CAS No.]]=VLOOKUP(표1[[#This Row],[CAS No.]], [1]규제DB_산안법_허용기준이하물질!$B:$D,1,FALSE),"제품 허용기준이하물질",""),"") | BK4: =IFERROR(VLOOKUP(표1[[#This Row],[CAS No.]], [1]규제DB_산안법_허용기준이하물질!$B:$D,3,FALSE),"") | BQ4: =IFERROR(VLOOKUP(표1[[#This Row],[CAS No.]], [1]규제DB_산안법_노출기준설정물질!$B:$K,8,FALSE),"") | BR4: =IFERROR(VLOOKUP(표1[[#This Row],[CAS No.]], [1]규제DB_산안법_노출기준설정물질!$B:$K,9,FALSE),"") | BS4: =IFERROR(VLOOKUP(표1[[#This Row],[CAS No.]], [1]규제DB_산안법_노출기준설정물질!$B:$K,10,FALSE),"") | BV4: =IFERROR(IF(VLOOKUP(표1[[#This Row],[CAS No.]],[1]규제DB_고용노동부고시_CMR!$B:$J,3,FALSE)="구분1A", IF(표1[[#This Row],[함량(W%)]]>=VLOOKUP(표1[[#This Row],[CAS No.]],[1]규제DB_고용노동부고시_CMR!$B:$J,4,FALSE),"제품 발암성물질",""), IF(VLOOKUP(표1[[#This Row],[CAS No.]],[1]규제DB_고용노동부고시_CMR!$B:$J,3,FALSE)="구분1B", IF(표1[[#This Row],[함량(W%)]]>=VLOOKUP(표1[[#This Row],[CAS No.]],[1]규제DB_고용노동부고시_CMR!$B:$J,4,FALSE),"제품 발암성물질",""), IF(VLOOKUP(표1[[#This Row],[CAS No.]],[1]규제DB_고용노동부고시_CMR!$B:$J,3,FALSE)="구분2", IF(표1[[#This Row],[함량(W%)]]>=VLOOKUP(표1[[#This Row],[CAS No.]],[1]규제DB_고용노동부고시_CMR!$B:$J,4,FALSE),"제품 발암성물질",""),""))),"") | BW4: =IFERROR(IF(VLOOKUP(표1[[#This Row],[CAS No.]],[1]규제DB_고용노동부고시_CMR!$B:$J,5,FALSE)="구분1A", IF(표1[[#This Row],[함량(W%)]]>=VLOOKUP(표1[[#This Row],[CAS No.]],[1]규제DB_고용노동부고시_CMR!$B:$J,6,FALSE),"제품 생식세포변이원성물질",""), IF(VLOOKUP(표1[[#This Row],[CAS No.]],[1]규제DB_고용노동부고시_CMR!$B:$J,5,FALSE)="구분1B", IF(표1[[#This Row],[함량(W%)]]>=VLOOKUP(표1[[#This Row],[CAS No.]],[1]규제DB_고용노동부고시_CMR!$B:$J,6,FALSE),"제품 생식세포변이원성물질",""), IF(VLOOKUP(표1[[#This Row],[CAS No.]],[1]규제DB_고용노동부고시_CMR!$B:$J,5,FALSE)="구분2", IF(표1[[#This Row],[함량(W%)]]>=VLOOKUP(표1[[#This Row],[CAS No.]],[1]규제DB_고용노동부고시_CMR!$B:$J,6,FALSE),"제품 생식세포변이원성물질",""),""))),"") | BX4: =IFERROR(IF(VLOOKUP(표1[[#This Row],[CAS No.]],[1]규제DB_고용노동부고시_CMR!$B:$J,7,FALSE)="구분1A", IF(표1[[#This Row],[함량(W%)]]>=VLOOKUP(표1[[#This Row],[CAS No.]],[1]규제DB_고용노동부고시_CMR!$B:$J,8,FALSE),"제품 생식독성물질",""), IF(VLOOKUP(표1[[#This Row],[CAS No.]],[1]규제DB_고용노동부고시_CMR!$B:$J,7,FALSE)="구분1B", IF(표1[[#This Row],[함량(W%)]]>=VLOOKUP(표1[[#This Row],[CAS No.]],[1]규제DB_고용노동부고시_CMR!$B:$J,8,FALSE),"제품 생식독성물질",""), IF(VLOOKUP(표1[[#This Row],[CAS No.]],[1]규제DB_고용노동부고시_CMR!$B:$J,7,FALSE)="구분2", IF(표1[[#This Row],[함량(W%)]]>=VLOOKUP(표1[[#This Row],[CAS No.]],[1]규제DB_고용노동부고시_CMR!$B:$J,8,FALSE),"제품 생식독성물질",""),""))),"") | BY4: =IFERROR(VLOOKUP(표1[[#This Row],[CAS No.]],[1]규제DB_위험물안전관리법_위험물!$B:$F,3,FALSE),"") | BZ4: =IFERROR(IF(표1[[#This Row],[CAS No.]]=VLOOKUP(표1[[#This Row],[CAS No.]],[1]규제DB_고압법_독성가스!$B:$D,1,FALSE),"독성가스",""),"") | CA4: =IFERROR(IF(표1[[#This Row],[CAS No.]]=VLOOKUP(표1[[#This Row],[CAS No.]],[1]규제DB_고압법_가연성가스!$B:$D,1,FALSE),"가연성가스",""),"") | CB4: =IFERROR(IF(표1[[#This Row],[CAS No.]]=VLOOKUP(표1[[#This Row],[CAS No.]],[1]규제DB_고압법_특수고압가스!$B:$D,1,FALSE),"특수고압가스",""),"") | CC4: =IFERROR(IF(표1[[#This Row],[CAS No.]]=VLOOKUP(표1[[#This Row],[CAS No.]],[1]규제DB_고압법_특정고압가스!$B:$D,1,FALSE),"특정고압가스",""),"") | CD4: =IFERROR(IF(표1[[#This Row],[함량(W%)]]>=VLOOKUP(표1[[#This Row],[CAS No.]],[1]규제DB_화관법_개별취급기준!$B:$G,5,FALSE),VLOOKUP(표1[[#This Row],[CAS No.]],[1]규제DB_화관법_개별취급기준!$B:$G,6,FALSE),""),"")
A5: 4 | C5: 삼화당피앤티 | E5: ho402 | F5: 내자 | G5: O | H5: 윤전 | I5: 인쇄 | J5: ㈜화승인더스트리 | K5: ㈜화승인더스트리 | M5: 원부자재 | N5: 옵셋 윤전 인쇄용 | O5: 혼합물 | P5: 고체 | Q5: 200 | R5: 200 | U5: 200 | V5: 200 | W5: =표1[[#This Row],[자재코드]]&"_"&표1[[#This Row],[자재명]]&"_"&표1[[#This Row],[공급업체명]] -> _ho402_㈜화승인더스트리 | X5: 폴리프로필렌(POLYPROPYLENE) | AB5: 79 | AC5: 코팅제 | AD5: X | AE5: O | AF5: O | AH5: 9003-07-0 | AI5: =IFERROR(표1[[#This Row],[사용량(kg)]]*표1[[#This Row],[함량(W%)]]/100,"") -> 158 | AR5: =IFERROR(IF(표1[[#This Row],[함량(W%)]]>=VLOOKUP(표1[[#This Row],[CAS No.]],[1]규제DB_유해법_유독물!B:F,5,FALSE),"유독물질 제품",""),"") | AS5: =IFERROR(VLOOKUP(표1[[#This Row],[CAS No.]],[1]규제DB_유해법_금지물질!B:G,3,FALSE),"") | AT5: =IFERROR(VLOOKUP(표1[[#This Row],[CAS No.]],[1]규제DB_유해법_금지물질!B:G,4,FALSE)&" 인지 확인하세요","") | AU5: =IFERROR(VLOOKUP(표1[[#This Row],[CAS No.]],[1]규제DB_유해법_제한물질!B:G,3,FALSE),"") | AV5: =IFERROR(IF(표1[[#This Row],[함량(W%)]]>=VLOOKUP(표1[[#This Row],[CAS No.]],[1]규제DB_유해법_제한물질!$B:$G,5,FALSE),"제한 제품",""),"") | BA5: =IFERROR(IF(표1[[#This Row],[함량(W%)]]>=VLOOKUP(표1[[#This Row],[CAS No.]],[1]규제DB_유해법_사고대비물질!$B:$J,4,FALSE),VLOOKUP(표1[[#This Row],[CAS No.]],[1]규제DB_유해법_사고대비물질!$B$2:$J$70,7,FALSE),""),"") | BB5: =IFERROR(IF(표1[[#This Row],[함량(W%)]]>=VLOOKUP(표1[[#This Row],[CAS No.]],[1]규제DB_유해법_사고대비물질!$B:$J,4,FALSE),VLOOKUP(표1[[#This Row],[CAS No.]],[1]규제DB_유해법_사고대비물질!$B$2:$J$70,8,FALSE),""),"") | BC5: =IFERROR(IF(표1[[#This Row],[함량(W%)]]>=VLOOKUP(표1[[#This Row],[CAS No.]],[1]규제DB_유해법_사고대비물질!$B:$J,4,FALSE),VLOOKUP(표1[[#This Row],[CAS No.]],[1]규제DB_유해법_사고대비물질!$B$2:$J$70,9,FALSE),""),"") | BD5: =IFERROR(IF(표1[[#This Row],[함량(W%)]]>=VLOOKUP(표1[[#This Row],[CAS No.]],'[1]규제DB_유해법_배출량조사 I'!$B:$D,3,FALSE),IF(VLOOKUP(표1[[#This Row],[CAS No.]],[1]기초자료!$A:$C,3,FALSE)>=1000,"배출량조사 I 물질",""),""),"") | BE5: =IFERROR(IF(표1[[#This Row],[함량(W%)]]>=VLOOKUP(표1[[#This Row],[CAS No.]],'[1]규제DB_유해법_배출량조사 II'!B:D,3,FALSE),IF(VLOOKUP(표1[[#This Row],[CAS No.]],[1]기초자료!$A:$C,3,FALSE)>=10000,"배출량조사 II 물질",""),""),"") | BF5: =IFERROR(IF(표1[[#This Row],[함량(W%)]]>=VLOOKUP(표1[[#This Row],[CAS No.]],[1]규제DB_산안법_금지물질!$B:$E,4,FALSE), VLOOKUP(표1[[#This Row],[CAS No.]],[1]규제DB_산안법_금지물질!$B:$E,2,FALSE)&" : "&VLOOKUP(표1[[#This Row],[CAS No.]],[1]규제DB_산안법_금지물질!$B:$E,3,FALSE)&" 인지 확인하세요",""),"") | BG5: =IFERROR(IF(표1[[#This Row],[함량(W%)]]>=VLOOKUP(표1[[#This Row],[CAS No.]],[1]규제DB_산안법_허가물질!$B:$E,4,FALSE), "제품 허가물질",""),"") | BH5: =IFERROR(IF(표1[[#This Row],[함량(W%)]]>=VLOOKUP(표1[[#This Row],[CAS No.]], [1]규제DB_산안법_특별관리물질!$B:$E,4,FALSE), "제품 특별관리물질",""),"") | BI5: =IFERROR(IF(표1[[#This Row],[함량(W%)]]>=VLOOKUP(표1[[#This Row],[CAS No.]], [1]규제DB_산안법_관리대상유해물질!$B:$E,4,FALSE), "제품 관리대상유해물질",""),"") | BJ5: =IFERROR(IF(표1[[#This Row],[CAS No.]]=VLOOKUP(표1[[#This Row],[CAS No.]], [1]규제DB_산안법_허용기준이하물질!$B:$D,1,FALSE),"제품 허용기준이하물질",""),"") | BK5: =IFERROR(VLOOKUP(표1[[#This Row],[CAS No.]], [1]규제DB_산안법_허용기준이하물질!$B:$D,3,FALSE),"") | BQ5: =IFERROR(VLOOKUP(표1[[#This Row],[CAS No.]], [1]규제DB_산안법_노출기준설정물질!$B:$K,8,FALSE),"") | BR5: =IFERROR(VLOOKUP(표1[[#This Row],[CAS No.]], [1]규제DB_산안법_노출기준설정물질!$B:$K,9,FALSE),"") | BS5: =IFERROR(VLOOKUP(표1[[#This Row],[CAS No.]], [1]규제DB_산안법_노출기준설정물질!$B:$K,10,FALSE),"") | BV5: =IFERROR(IF(VLOOKUP(표1[[#This Row],[CAS No.]],[1]규제DB_고용노동부고시_CMR!$B:$J,3,FALSE)="구분1A", IF(표1[[#This Row],[함량(W%)]]>=VLOOKUP(표1[[#This Row],[CAS No.]],[1]규제DB_고용노동부고시_CMR!$B:$J,4,FALSE),"제품 발암성물질",""), IF(VLOOKUP(표1[[#This Row],[CAS No.]],[1]규제DB_고용노동부고시_CMR!$B:$J,3,FALSE)="구분1B", IF(표1[[#This Row],[함량(W%)]]>=VLOOKUP(표1[[#This Row],[CAS No.]],[1]규제DB_고용노동부고시_CMR!$B:$J,4,FALSE),"제품 발암성물질",""), IF(VLOOKUP(표1[[#This Row],[CAS No.]],[1]규제DB_고용노동부고시_CMR!$B:$J,3,FALSE)="구분2", IF(표1[[#This Row],[함량(W%)]]>=VLOOKUP(표1[[#This Row],[CAS No.]],[1]규제DB_고용노동부고시_CMR!$B:$J,4,FALSE),"제품 발암성물질",""),""))),"") | BW5: =IFERROR(IF(VLOOKUP(표1[[#This Row],[CAS No.]],[1]규제DB_고용노동부고시_CMR!$B:$J,5,FALSE)="구분1A", IF(표1[[#This Row],[함량(W%)]]>=VLOOKUP(표1[[#This Row],[CAS No.]],[1]규제DB_고용노동부고시_CMR!$B:$J,6,FALSE),"제품 생식세포변이원성물질",""), IF(VLOOKUP(표1[[#This Row],[CAS No.]],[1]규제DB_고용노동부고시_CMR!$B:$J,5,FALSE)="구분1B", IF(표1[[#This Row],[함량(W%)]]>=VLOOKUP(표1[[#This Row],[CAS No.]],[1]규제DB_고용노동부고시_CMR!$B:$J,6,FALSE),"제품 생식세포변이원성물질",""), IF(VLOOKUP(표1[[#This Row],[CAS No.]],[1]규제DB_고용노동부고시_CMR!$B:$J,5,FALSE)="구분2", IF(표1[[#This Row],[함량(W%)]]>=VLOOKUP(표1[[#This Row],[CAS No.]],[1]규제DB_고용노동부고시_CMR!$B:$J,6,FALSE),"제품 생식세포변이원성물질",""),""))),"") | BX5: =IFERROR(IF(VLOOKUP(표1[[#This Row],[CAS No.]],[1]규제DB_고용노동부고시_CMR!$B:$J,7,FALSE)="구분1A", IF(표1[[#This Row],[함량(W%)]]>=VLOOKUP(표1[[#This Row],[CAS No.]],[1]규제DB_고용노동부고시_CMR!$B:$J,8,FALSE),"제품 생식독성물질",""), IF(VLOOKUP(표1[[#This Row],[CAS No.]],[1]규제DB_고용노동부고시_CMR!$B:$J,7,FALSE)="구분1B", IF(표1[[#This Row],[함량(W%)]]>=VLOOKUP(표1[[#This Row],[CAS No.]],[1]규제DB_고용노동부고시_CMR!$B:$J,8,FALSE),"제품 생식독성물질",""), IF(VLOOKUP(표1[[#This Row],[CAS No.]],[1]규제DB_고용노동부고시_CMR!$B:$J,7,FALSE)="구분2", IF(표1[[#This Row],[함량(W%)]]>=VLOOKUP(표1[[#This Row],[CAS No.]],[1]규제DB_고용노동부고시_CMR!$B:$J,8,FALSE),"제품 생식독성물질",""),""))),"") | BY5: =IFERROR(VLOOKUP(표1[[#This Row],[CAS No.]],[1]규제DB_위험물안전관리법_위험물!$B:$F,3,FALSE),"") | BZ5: =IFERROR(IF(표1[[#This Row],[CAS No.]]=VLOOKUP(표1[[#This Row],[CAS No.]],[1]규제DB_고압법_독성가스!$B:$D,1,FALSE),"독성가스",""),"") | CA5: =IFERROR(IF(표1[[#This Row],[CAS No.]]=VLOOKUP(표1[[#This Row],[CAS No.]],[1]규제DB_고압법_가연성가스!$B:$D,1,FALSE),"가연성가스",""),"") | CB5: =IFERROR(IF(표1[[#This Row],[CAS No.]]=VLOOKUP(표1[[#This Row],[CAS No.]],[1]규제DB_고압법_특수고압가스!$B:$D,1,FALSE),"특수고압가스",""),"") | CC5: =IFERROR(IF(표1[[#This Row],[CAS No.]]=VLOOKUP(표1[[#This Row],[CAS No.]],[1]규제DB_고압법_특정고압가스!$B:$D,1,FALSE),"특정고압가스",""),"") | CD5: =IFERROR(IF(표1[[#This Row],[함량(W%)]]>=VLOOKUP(표1[[#This Row],[CAS No.]],[1]규제DB_화관법_개별취급기준!$B:$G,5,FALSE),VLOOKUP(표1[[#This Row],[CAS No.]],[1]규제DB_화관법_개별취급기준!$B:$G,6,FALSE),""),"")
A6: 5 | C6: 삼화당피앤티 | E6: hb-302 | F6: 내자 | G6: O | H6: 윤전 | I6: 인쇄 | J6: ㈜화승인더스트리 | K6: ㈜화승인더스트리 | M6: 원부자재 | N6: 옵셋 윤전 인쇄용 | O6: 혼합물 | P6: 고체 | Q6: 2800 | R6: 2800 | U6: 2800 | V6: 2800 | W6: =표1[[#This Row],[자재코드]]&"_"&표1[[#This Row],[자재명]]&"_"&표1[[#This Row],[공급업체명]] -> _hb-302_㈜화승인더스트리 | X6: 실리카 수화물 | AB6: 0.9 | AC6: 코팅제 | AD6: X | AE6: O | AF6: O | AH6: 112926-00-8 | AI6: =IFERROR(표1[[#This Row],[사용량(kg)]]*표1[[#This Row],[함량(W%)]]/100,"") -> 25.2 | AR6: =IFERROR(IF(표1[[#This Row],[함량(W%)]]>=VLOOKUP(표1[[#This Row],[CAS No.]],[1]규제DB_유해법_유독물!B:F,5,FALSE),"유독물질 제품",""),"") | AS6: =IFERROR(VLOOKUP(표1[[#This Row],[CAS No.]],[1]규제DB_유해법_금지물질!B:G,3,FALSE),"") | AT6: =IFERROR(VLOOKUP(표1[[#This Row],[CAS No.]],[1]규제DB_유해법_금지물질!B:G,4,FALSE)&" 인지 확인하세요","") | AU6: =IFERROR(VLOOKUP(표1[[#This Row],[CAS No.]],[1]규제DB_유해법_제한물질!B:G,3,FALSE),"") | AV6: =IFERROR(IF(표1[[#This Row],[함량(W%)]]>=VLOOKUP(표1[[#This Row],[CAS No.]],[1]규제DB_유해법_제한물질!$B:$G,5,FALSE),"제한 제품",""),"") | BA6: =IFERROR(IF(표1[[#This Row],[함량(W%)]]>=VLOOKUP(표1[[#This Row],[CAS No.]],[1]규제DB_유해법_사고대비물질!$B:$J,4,FALSE),VLOOKUP(표1[[#This Row],[CAS No.]],[1]규제DB_유해법_사고대비물질!$B$2:$J$70,7,FALSE),""),"") | BB6: =IFERROR(IF(표1[[#This Row],[함량(W%)]]>=VLOOKUP(표1[[#This Row],[CAS No.]],[1]규제DB_유해법_사고대비물질!$B:$J,4,FALSE),VLOOKUP(표1[[#This Row],[CAS No.]],[1]규제DB_유해법_사고대비물질!$B$2:$J$70,8,FALSE),""),"") | BC6: =IFERROR(IF(표1[[#This Row],[함량(W%)]]>=VLOOKUP(표1[[#This Row],[CAS No.]],[1]규제DB_유해법_사고대비물질!$B:$J,4,FALSE),VLOOKUP(표1[[#This Row],[CAS No.]],[1]규제DB_유해법_사고대비물질!$B$2:$J$70,9,FALSE),""),"") | BD6: =IFERROR(IF(표1[[#This Row],[함량(W%)]]>=VLOOKUP(표1[[#This Row],[CAS No.]],'[1]규제DB_유해법_배출량조사 I'!$B:$D,3,FALSE),IF(VLOOKUP(표1[[#This Row],[CAS No.]],[1]기초자료!$A:$C,3,FALSE)>=1000,"배출량조사 I 물질",""),""),"") | BE6: =IFERROR(IF(표1[[#This Row],[함량(W%)]]>=VLOOKUP(표1[[#This Row],[CAS No.]],'[1]규제DB_유해법_배출량조사 II'!B:D,3,FALSE),IF(VLOOKUP(표1[[#This Row],[CAS No.]],[1]기초자료!$A:$C,3,FALSE)>=10000,"배출량조사 II 물질",""),""),"") | BF6: =IFERROR(IF(표1[[#This Row],[함량(W%)]]>=VLOOKUP(표1[[#This Row],[CAS No.]],[1]규제DB_산안법_금지물질!$B:$E,4,FALSE), VLOOKUP(표1[[#This Row],[CAS No.]],[1]규제DB_산안법_금지물질!$B:$E,2,FALSE)&" : "&VLOOKUP(표1[[#This Row],[CAS No.]],[1]규제DB_산안법_금지물질!$B:$E,3,FALSE)&" 인지 확인하세요",""),"") | BG6: =IFERROR(IF(표1[[#This Row],[함량(W%)]]>=VLOOKUP(표1[[#This Row],[CAS No.]],[1]규제DB_산안법_허가물질!$B:$E,4,FALSE), "제품 허가물질",""),"") | BH6: =IFERROR(IF(표1[[#This Row],[함량(W%)]]>=VLOOKUP(표1[[#This Row],[CAS No.]], [1]규제DB_산안법_특별관리물질!$B:$E,4,FALSE), "제품 특별관리물질",""),"") | BI6: =IFERROR(IF(표1[[#This Row],[함량(W%)]]>=VLOOKUP(표1[[#This Row],[CAS No.]], [1]규제DB_산안법_관리대상유해물질!$B:$E,4,FALSE), "제품 관리대상유해물질",""),"") | BJ6: =IFERROR(IF(표1[[#This Row],[CAS No.]]=VLOOKUP(표1[[#This Row],[CAS No.]], [1]규제DB_산안법_허용기준이하물질!$B:$D,1,FALSE),"제품 허용기준이하물질",""),"") | BK6: =IFERROR(VLOOKUP(표1[[#This Row],[CAS No.]], [1]규제DB_산안법_허용기준이하물질!$B:$D,3,FALSE),"") | BQ6: =IFERROR(VLOOKUP(표1[[#This Row],[CAS No.]], [1]규제DB_산안법_노출기준설정물질!$B:$K,8,FALSE),"") | BR6: =IFERROR(VLOOKUP(표1[[#This Row],[CAS No.]], [1]규제DB_산안법_노출기준설정물질!$B:$K,9,FALSE),"") | BS6: =IFERROR(VLOOKUP(표1[[#This Row],[CAS No.]], [1]규제DB_산안법_노출기준설정물질!$B:$K,10,FALSE),"") | BV6: =IFERROR(IF(VLOOKUP(표1[[#This Row],[CAS No.]],[1]규제DB_고용노동부고시_CMR!$B:$J,3,FALSE)="구분1A", IF(표1[[#This Row],[함량(W%)]]>=VLOOKUP(표1[[#This Row],[CAS No.]],[1]규제DB_고용노동부고시_CMR!$B:$J,4,FALSE),"제품 발암성물질",""), IF(VLOOKUP(표1[[#This Row],[CAS No.]],[1]규제DB_고용노동부고시_CMR!$B:$J,3,FALSE)="구분1B", IF(표1[[#This Row],[함량(W%)]]>=VLOOKUP(표1[[#This Row],[CAS No.]],[1]규제DB_고용노동부고시_CMR!$B:$J,4,FALSE),"제품 발암성물질",""), IF(VLOOKUP(표1[[#This Row],[CAS No.]],[1]규제DB_고용노동부고시_CMR!$B:$J,3,FALSE)="구분2", IF(표1[[#This Row],[함량(W%)]]>=VLOOKUP(표1[[#This Row],[CAS No.]],[1]규제DB_고용노동부고시_CMR!$B:$J,4,FALSE),"제품 발암성물질",""),""))),"") | BW6: =IFERROR(IF(VLOOKUP(표1[[#This Row],[CAS No.]],[1]규제DB_고용노동부고시_CMR!$B:$J,5,FALSE)="구분1A", IF(표1[[#This Row],[함량(W%)]]>=VLOOKUP(표1[[#This Row],[CAS No.]],[1]규제DB_고용노동부고시_CMR!$B:$J,6,FALSE),"제품 생식세포변이원성물질",""), IF(VLOOKUP(표1[[#This Row],[CAS No.]],[1]규제DB_고용노동부고시_CMR!$B:$J,5,FALSE)="구분1B", IF(표1[[#This Row],[함량(W%)]]>=VLOOKUP(표1[[#This Row],[CAS No.]],[1]규제DB_고용노동부고시_CMR!$B:$J,6,FALSE),"제품 생식세포변이원성물질",""), IF(VLOOKUP(표1[[#This Row],[CAS No.]],[1]규제DB_고용노동부고시_CMR!$B:$J,5,FALSE)="구분2", IF(표1[[#This Row],[함량(W%)]]>=VLOOKUP(표1[[#This Row],[CAS No.]],[1]규제DB_고용노동부고시_CMR!$B:$J,6,FALSE),"제품 생식세포변이원성물질",""),""))),"") | BX6: =IFERROR(IF(VLOOKUP(표1[[#This Row],[CAS No.]],[1]규제DB_고용노동부고시_CMR!$B:$J,7,FALSE)="구분1A", IF(표1[[#This Row],[함량(W%)]]>=VLOOKUP(표1[[#This Row],[CAS No.]],[1]규제DB_고용노동부고시_CMR!$B:$J,8,FALSE),"제품 생식독성물질",""), IF(VLOOKUP(표1[[#This Row],[CAS No.]],[1]규제DB_고용노동부고시_CMR!$B:$J,7,FALSE)="구분1B", IF(표1[[#This Row],[함량(W%)]]>=VLOOKUP(표1[[#This Row],[CAS No.]],[1]규제DB_고용노동부고시_CMR!$B:$J,8,FALSE),"제품 생식독성물질",""), IF(VLOOKUP(표1[[#This Row],[CAS No.]],[1]규제DB_고용노동부고시_CMR!$B:$J,7,FALSE)="구분2", IF(표1[[#This Row],[함량(W%)]]>=VLOOKUP(표1[[#This Row],[CAS No.]],[1]규제DB_고용노동부고시_CMR!$B:$J,8,FALSE),"제품 생식독성물질",""),""))),"") | BY6: =IFERROR(VLOOKUP(표1[[#This Row],[CAS No.]],[1]규제DB_위험물안전관리법_위험물!$B:$F,3,FALSE),"") | BZ6: =IFERROR(IF(표1[[#This Row],[CAS No.]]=VLOOKUP(표1[[#This Row],[CAS No.]],[1]규제DB_고압법_독성가스!$B:$D,1,FALSE),"독성가스",""),"") | CA6: =IFERROR(IF(표1[[#This Row],[CAS No.]]=VLOOKUP(표1[[#This Row],[CAS No.]],[1]규제DB_고압법_가연성가스!$B:$D,1,FALSE),"가연성가스",""),"") | CB6: =IFERROR(IF(표1[[#This Row],[CAS No.]]=VLOOKUP(표1[[#This Row],[CAS No.]],[1]규제DB_고압법_특수고압가스!$B:$D,1,FALSE),"특수고압가스",""),"") | CC6: =IFERROR(IF(표1[[#This Row],[CAS No.]]=VLOOKUP(표1[[#This Row],[CAS No.]],[1]규제DB_고압법_특정고압가스!$B:$D,1,FALSE),"특정고압가스",""),"") | CD6: =IFERROR(IF(표1[[#This Row],[함량(W%)]]>=VLOOKUP(표1[[#This Row],[CAS No.]],[1]규제DB_화관법_개별취급기준!$B:$G,5,FALSE),VLOOKUP(표1[[#This Row],[CAS No.]],[1]규제DB_화관법_개별취급기준!$B:$G,6,FALSE),""),"")
A7: 6 | C7: 삼화당피앤티 | E7: hb 302 | F7: 내자 | G7: O | H7: 윤전 | I7: 인쇄 | J7: ㈜화승인더스트리 | K7: ㈜화승인더스트리 | M7: 원부자재 | N7: 옵셋 윤전 인쇄용 | O7: 혼합물 | P7: 고체 | Q7: 2800 | R7: 2800 | U7: 2800 | V7: 2800 | W7: =표1[[#This Row],[자재코드]]&"_"&표1[[#This Row],[자재명]]&"_"&표1[[#This Row],[공급업체명]] -> _hb 302_㈜화승인더스트리 | X7: 폴리프로필렌(POLYPROPYLENE) | AB7: 99 | AC7: 코팅제 | AD7: X | AE7: O | AF7: O | AH7: 9003-07-0 | AI7: =IFERROR(표1[[#This Row],[사용량(kg)]]*표1[[#This Row],[함량(W%)]]/100,"") -> 2772 | AR7: =IFERROR(IF(표1[[#This Row],[함량(W%)]]>=VLOOKUP(표1[[#This Row],[CAS No.]],[1]규제DB_유해법_유독물!B:F,5,FALSE),"유독물질 제품",""),"") | AS7: =IFERROR(VLOOKUP(표1[[#This Row],[CAS No.]],[1]규제DB_유해법_금지물질!B:G,3,FALSE),"") | AT7: =IFERROR(VLOOKUP(표1[[#This Row],[CAS No.]],[1]규제DB_유해법_금지물질!B:G,4,FALSE)&" 인지 확인하세요","") | AU7: =IFERROR(VLOOKUP(표1[[#This Row],[CAS No.]],[1]규제DB_유해법_제한물질!B:G,3,FALSE),"") | AV7: =IFERROR(IF(표1[[#This Row],[함량(W%)]]>=VLOOKUP(표1[[#This Row],[CAS No.]],[1]규제DB_유해법_제한물질!$B:$G,5,FALSE),"제한 제품",""),"") | BA7: =IFERROR(IF(표1[[#This Row],[함량(W%)]]>=VLOOKUP(표1[[#This Row],[CAS No.]],[1]규제DB_유해법_사고대비물질!$B:$J,4,FALSE),VLOOKUP(표1[[#This Row],[CAS No.]],[1]규제DB_유해법_사고대비물질!$B$2:$J$70,7,FALSE),""),"") | BB7: =IFERROR(IF(표1[[#This Row],[함량(W%)]]>=VLOOKUP(표1[[#This Row],[CAS No.]],[1]규제DB_유해법_사고대비물질!$B:$J,4,FALSE),VLOOKUP(표1[[#This Row],[CAS No.]],[1]규제DB_유해법_사고대비물질!$B$2:$J$70,8,FALSE),""),"") | BC7: =IFERROR(IF(표1[[#This Row],[함량(W%)]]>=VLOOKUP(표1[[#This Row],[CAS No.]],[1]규제DB_유해법_사고대비물질!$B:$J,4,FALSE),VLOOKUP(표1[[#This Row],[CAS No.]],[1]규제DB_유해법_사고대비물질!$B$2:$J$70,9,FALSE),""),"") | BD7: =IFERROR(IF(표1[[#This Row],[함량(W%)]]>=VLOOKUP(표1[[#This Row],[CAS No.]],'[1]규제DB_유해법_배출량조사 I'!$B:$D,3,FALSE),IF(VLOOKUP(표1[[#This Row],[CAS No.]],[1]기초자료!$A:$C,3,FALSE)>=1000,"배출량조사 I 물질",""),""),"") | BE7: =IFERROR(IF(표1[[#This Row],[함량(W%)]]>=VLOOKUP(표1[[#This Row],[CAS No.]],'[1]규제DB_유해법_배출량조사 II'!B:D,3,FALSE),IF(VLOOKUP(표1[[#This Row],[CAS No.]],[1]기초자료!$A:$C,3,FALSE)>=10000,"배출량조사 II 물질",""),""),"") | BF7: =IFERROR(IF(표1[[#This Row],[함량(W%)]]>=VLOOKUP(표1[[#This Row],[CAS No.]],[1]규제DB_산안법_금지물질!$B:$E,4,FALSE), VLOOKUP(표1[[#This Row],[CAS No.]],[1]규제DB_산안법_금지물질!$B:$E,2,FALSE)&" : "&VLOOKUP(표1[[#This Row],[CAS No.]],[1]규제DB_산안법_금지물질!$B:$E,3,FALSE)&" 인지 확인하세요",""),"") | BG7: =IFERROR(IF(표1[[#This Row],[함량(W%)]]>=VLOOKUP(표1[[#This Row],[CAS No.]],[1]규제DB_산안법_허가물질!$B:$E,4,FALSE), "제품 허가물질",""),"") | BH7: =IFERROR(IF(표1[[#This Row],[함량(W%)]]>=VLOOKUP(표1[[#This Row],[CAS No.]], [1]규제DB_산안법_특별관리물질!$B:$E,4,FALSE), "제품 특별관리물질",""),"") | BJ7: =IFERROR(IF(표1[[#This Row],[CAS No.]]=VLOOKUP(표1[[#This Row],[CAS No.]], [1]규제DB_산안법_허용기준이하물질!$B:$D,1,FALSE),"제품 허용기준이하물질",""),"") | BK7: =IFERROR(VLOOKUP(표1[[#This Row],[CAS No.]], [1]규제DB_산안법_허용기준이하물질!$B:$D,3,FALSE),"") | BQ7: =IFERROR(VLOOKUP(표1[[#This Row],[CAS No.]], [1]규제DB_산안법_노출기준설정물질!$B:$K,8,FALSE),"") | BR7: =IFERROR(VLOOKUP(표1[[#This Row],[CAS No.]], [1]규제DB_산안법_노출기준설정물질!$B:$K,9,FALSE),"") | BS7: =IFERROR(VLOOKUP(표1[[#This Row],[CAS No.]], [1]규제DB_산안법_노출기준설정물질!$B:$K,10,FALSE),"") | BV7: =IFERROR(IF(VLOOKUP(표1[[#This Row],[CAS No.]],[1]규제DB_고용노동부고시_CMR!$B:$J,3,FALSE)="구분1A", IF(표1[[#This Row],[함량(W%)]]>=VLOOKUP(표1[[#This Row],[CAS No.]],[1]규제DB_고용노동부고시_CMR!$B:$J,4,FALSE),"제품 발암성물질",""), IF(VLOOKUP(표1[[#This Row],[CAS No.]],[1]규제DB_고용노동부고시_CMR!$B:$J,3,FALSE)="구분1B", IF(표1[[#This Row],[함량(W%)]]>=VLOOKUP(표1[[#This Row],[CAS No.]],[1]규제DB_고용노동부고시_CMR!$B:$J,4,FALSE),"제품 발암성물질",""), IF(VLOOKUP(표1[[#This Row],[CAS No.]],[1]규제DB_고용노동부고시_CMR!$B:$J,3,FALSE)="구분2", IF(표1[[#This Row],[함량(W%)]]>=VLOOKUP(표1[[#This Row],[CAS No.]],[1]규제DB_고용노동부고시_CMR!$B:$J,4,FALSE),"제품 발암성물질",""),""))),"") | BW7: =IFERROR(IF(VLOOKUP(표1[[#This Row],[CAS No.]],[1]규제DB_고용노동부고시_CMR!$B:$J,5,FALSE)="구분1A", IF(표1[[#This Row],[함량(W%)]]>=VLOOKUP(표1[[#This Row],[CAS No.]],[1]규제DB_고용노동부고시_CMR!$B:$J,6,FALSE),"제품 생식세포변이원성물질",""), IF(VLOOKUP(표1[[#This Row],[CAS No.]],[1]규제DB_고용노동부고시_CMR!$B:$J,5,FALSE)="구분1B", IF(표1[[#This Row],[함량(W%)]]>=VLOOKUP(표1[[#This Row],[CAS No.]],[1]규제DB_고용노동부고시_CMR!$B:$J,6,FALSE),"제품 생식세포변이원성물질",""), IF(VLOOKUP(표1[[#This Row],[CAS No.]],[1]규제DB_고용노동부고시_CMR!$B:$J,5,FALSE)="구분2", IF(표1[[#This Row],[함량(W%)]]>=VLOOKUP(표1[[#This Row],[CAS No.]],[1]규제DB_고용노동부고시_CMR!$B:$J,6,FALSE),"제품 생식세포변이원성물질",""),""))),"") | BX7: =IFERROR(IF(VLOOKUP(표1[[#This Row],[CAS No.]],[1]규제DB_고용노동부고시_CMR!$B:$J,7,FALSE)="구분1A", IF(표1[[#This Row],[함량(W%)]]>=VLOOKUP(표1[[#This Row],[CAS No.]],[1]규제DB_고용노동부고시_CMR!$B:$J,8,FALSE),"제품 생식독성물질",""), IF(VLOOKUP(표1[[#This Row],[CAS No.]],[1]규제DB_고용노동부고시_CMR!$B:$J,7,FALSE)="구분1B", IF(표1[[#This Row],[함량(W%)]]>=VLOOKUP(표1[[#This Row],[CAS No.]],[1]규제DB_고용노동부고시_CMR!$B:$J,8,FALSE),"제품 생식독성물질",""), IF(VLOOKUP(표1[[#This Row],[CAS No.]],[1]규제DB_고용노동부고시_CMR!$B:$J,7,FALSE)="구분2", IF(표1[[#This Row],[함량(W%)]]>=VLOOKUP(표1[[#This Row],[CAS No.]],[1]규제DB_고용노동부고시_CMR!$B:$J,8,FALSE),"제품 생식독성물질",""),""))),"") | BY7: =IFERROR(VLOOKUP(표1[[#This Row],[CAS No.]],[1]규제DB_위험물안전관리법_위험물!$B:$F,3,FALSE),"") | BZ7: =IFERROR(IF(표1[[#This Row],[CAS No.]]=VLOOKUP(표1[[#This Row],[CAS No.]],[1]규제DB_고압법_독성가스!$B:$D,1,FALSE),"독성가스",""),"") | CA7: =IFERROR(IF(표1[[#This Row],[CAS No.]]=VLOOKUP(표1[[#This Row],[CAS No.]],[1]규제DB_고압법_가연성가스!$B:$D,1,FALSE),"가연성가스",""),"") | CB7: =IFERROR(IF(표1[[#This Row],[CAS No.]]=VLOOKUP(표1[[#This Row],[CAS No.]],[1]규제DB_고압법_특수고압가스!$B:$D,1,FALSE),"특수고압가스",""),"") | CC7: =IFERROR(IF(표1[[#This Row],[CAS No.]]=VLOOKUP(표1[[#This Row],[CAS No.]],[1]규제DB_고압법_특정고압가스!$B:$D,1,FALSE),"특정고압가스",""),"") | CD7: =IFERROR(IF(표1[[#This Row],[함량(W%)]]>=VLOOKUP(표1[[#This Row],[CAS No.]],[1]규제DB_화관법_개별취급기준!$B:$G,5,FALSE),VLOOKUP(표1[[#This Row],[CAS No.]],[1]규제DB_화관법_개별취급기준!$B:$G,6,FALSE),""),"")
A8: 7 | C8: 삼화당피앤티 | E8: soocoat av-208mf | F8: 내자 | G8: O | H8: 윤전 | I8: 인쇄 | J8: ㈜수케미칼 | K8: ㈜수케미칼 | M8: 원부자재 | N8: 옵셋 윤전 인쇄용 | O8: 혼합물 | P8: 액체 | Q8: 2800 | R8: 2800 | U8: 2800 | V8: 2800 | W8: =표1[[#This Row],[자재코드]]&"_"&표1[[#This Row],[자재명]]&"_"&표1[[#This Row],[공급업체명]] -> _soocoat av-208mf_㈜수케미칼 | X8: 암모니아 | AB8: 0.09 | AC8: 코팅제 | AD8: X | AE8: O | AF8: O | AH8: 7664-41-7 | AI8: =IFERROR(표1[[#This Row],[사용량(kg)]]*표1[[#This Row],[함량(W%)]]/100,"") -> 2.52 | AR8: =IFERROR(IF(표1[[#This Row],[함량(W%)]]>=VLOOKUP(표1[[#This Row],[CAS No.]],[1]규제DB_유해법_유독물!B:F,5,FALSE),"유독물질 제품",""),"") | AS8: =IFERROR(VLOOKUP(표1[[#This Row],[CAS No.]],[1]규제DB_유해법_금지물질!B:G,3,FALSE),"") | AT8: =IFERROR(VLOOKUP(표1[[#This Row],[CAS No.]],[1]규제DB_유해법_금지물질!B:G,4,FALSE)&" 인지 확인하세요","") | AU8: =IFERROR(VLOOKUP(표1[[#This Row],[CAS No.]],[1]규제DB_유해법_제한물질!B:G,3,FALSE),"") | AV8: =IFERROR(IF(표1[[#This Row],[함량(W%)]]>=VLOOKUP(표1[[#This Row],[CAS No.]],[1]규제DB_유해법_제한물질!$B:$G,5,FALSE),"제한 제품",""),"") | BA8: =IFERROR(IF(표1[[#This Row],[함량(W%)]]>=VLOOKUP(표1[[#This Row],[CAS No.]],[1]규제DB_유해법_사고대비물질!$B:$J,4,FALSE),VLOOKUP(표1[[#This Row],[CAS No.]],[1]규제DB_유해법_사고대비물질!$B$2:$J$70,7,FALSE),""),"") | BB8: =IFERROR(IF(표1[[#This Row],[함량(W%)]]>=VLOOKUP(표1[[#This Row],[CAS No.]],[1]규제DB_유해법_사고대비물질!$B:$J,4,FALSE),VLOOKUP(표1[[#This Row],[CAS No.]],[1]규제DB_유해법_사고대비물질!$B$2:$J$70,8,FALSE),""),"") | BC8: =IFERROR(IF(표1[[#This Row],[함량(W%)]]>=VLOOKUP(표1[[#This Row],[CAS No.]],[1]규제DB_유해법_사고대비물질!$B:$J,4,FALSE),VLOOKUP(표1[[#This Row],[CAS No.]],[1]규제DB_유해법_사고대비물질!$B$2:$J$70,9,FALSE),""),"") | BD8: =IFERROR(IF(표1[[#This Row],[함량(W%)]]>=VLOOKUP(표1[[#This Row],[CAS No.]],'[1]규제DB_유해법_배출량조사 I'!$B:$D,3,FALSE),IF(VLOOKUP(표1[[#This Row],[CAS No.]],[1]기초자료!$A:$C,3,FALSE)>=1000,"배출량조사 I 물질",""),""),"") | BF8: =IFERROR(IF(표1[[#This Row],[함량(W%)]]>=VLOOKUP(표1[[#This Row],[CAS No.]],[1]규제DB_산안법_금지물질!$B:$E,4,FALSE), VLOOKUP(표1[[#This Row],[CAS No.]],[1]규제DB_산안법_금지물질!$B:$E,2,FALSE)&" : "&VLOOKUP(표1[[#This Row],[CAS No.]],[1]규제DB_산안법_금지물질!$B:$E,3,FALSE)&" 인지 확인하세요",""),"") | BG8: =IFERROR(IF(표1[[#This Row],[함량(W%)]]>=VLOOKUP(표1[[#This Row],[CAS No.]],[1]규제DB_산안법_허가물질!$B:$E,4,FALSE), "제품 허가물질",""),"") | BH8: =IFERROR(IF(표1[[#This Row],[함량(W%)]]>=VLOOKUP(표1[[#This Row],[CAS No.]], [1]규제DB_산안법_특별관리물질!$B:$E,4,FALSE), "제품 특별관리물질",""),"") | BJ8: =IFERROR(IF(표1[[#This Row],[CAS No.]]=VLOOKUP(표1[[#This Row],[CAS No.]], [1]규제DB_산안법_허용기준이하물질!$B:$D,1,FALSE),"제품 허용기준이하물질",""),"") | BK8: =IFERROR(VLOOKUP(표1[[#This Row],[CAS No.]], [1]규제DB_산안법_허용기준이하물질!$B:$D,3,FALSE),"") | BQ8: =IFERROR(VLOOKUP(표1[[#This Row],[CAS No.]], [1]규제DB_산안법_노출기준설정물질!$B:$K,8,FALSE),"") | BR8: =IFERROR(VLOOKUP(표1[[#This Row],[CAS No.]], [1]규제DB_산안법_노출기준설정물질!$B:$K,9,FALSE),"") | BS8: =IFERROR(VLOOKUP(표1[[#This Row],[CAS No.]], [1]규제DB_산안법_노출기준설정물질!$B:$K,10,FALSE),"") | BV8: =IFERROR(IF(VLOOKUP(표1[[#This Row],[CAS No.]],[1]규제DB_고용노동부고시_CMR!$B:$J,3,FALSE)="구분1A", IF(표1[[#This Row],[함량(W%)]]>=VLOOKUP(표1[[#This Row],[CAS No.]],[1]규제DB_고용노동부고시_CMR!$B:$J,4,FALSE),"제품 발암성물질",""), IF(VLOOKUP(표1[[#This Row],[CAS No.]],[1]규제DB_고용노동부고시_CMR!$B:$J,3,FALSE)="구분1B", IF(표1[[#This Row],[함량(W%)]]>=VLOOKUP(표1[[#This Row],[CAS No.]],[1]규제DB_고용노동부고시_CMR!$B:$J,4,FALSE),"제품 발암성물질",""), IF(VLOOKUP(표1[[#This Row],[CAS No.]],[1]규제DB_고용노동부고시_CMR!$B:$J,3,FALSE)="구분2", IF(표1[[#This Row],[함량(W%)]]>=VLOOKUP(표1[[#This Row],[CAS No.]],[1]규제DB_고용노동부고시_CMR!$B:$J,4,FALSE),"제품 발암성물질",""),""))),"") | BW8: =IFERROR(IF(VLOOKUP(표1[[#This Row],[CAS No.]],[1]규제DB_고용노동부고시_CMR!$B:$J,5,FALSE)="구분1A", IF(표1[[#This Row],[함량(W%)]]>=VLOOKUP(표1[[#This Row],[CAS No.]],[1]규제DB_고용노동부고시_CMR!$B:$J,6,FALSE),"제품 생식세포변이원성물질",""), IF(VLOOKUP(표1[[#This Row],[CAS No.]],[1]규제DB_고용노동부고시_CMR!$B:$J,5,FALSE)="구분1B", IF(표1[[#This Row],[함량(W%)]]>=VLOOKUP(표1[[#This Row],[CAS No.]],[1]규제DB_고용노동부고시_CMR!$B:$J,6,FALSE),"제품 생식세포변이원성물질",""), IF(VLOOKUP(표1[[#This Row],[CAS No.]],[1]규제DB_고용노동부고시_CMR!$B:$J,5,FALSE)="구분2", IF(표1[[#This Row],[함량(W%)]]>=VLOOKUP(표1[[#This Row],[CAS No.]],[1]규제DB_고용노동부고시_CMR!$B:$J,6,FALSE),"제품 생식세포변이원성물질",""),""))),"") | BX8: =IFERROR(IF(VLOOKUP(표1[[#This Row],[CAS No.]],[1]규제DB_고용노동부고시_CMR!$B:$J,7,FALSE)="구분1A", IF(표1[[#This Row],[함량(W%)]]>=VLOOKUP(표1[[#This Row],[CAS No.]],[1]규제DB_고용노동부고시_CMR!$B:$J,8,FALSE),"제품 생식독성물질",""), IF(VLOOKUP(표1[[#This Row],[CAS No.]],[1]규제DB_고용노동부고시_CMR!$B:$J,7,FALSE)="구분1B", IF(표1[[#This Row],[함량(W%)]]>=VLOOKUP(표1[[#This Row],[CAS No.]],[1]규제DB_고용노동부고시_CMR!$B:$J,8,FALSE),"제품 생식독성물질",""), IF(VLOOKUP(표1[[#This Row],[CAS No.]],[1]규제DB_고용노동부고시_CMR!$B:$J,7,FALSE)="구분2", IF(표1[[#This Row],[함량(W%)]]>=VLOOKUP(표1[[#This Row],[CAS No.]],[1]규제DB_고용노동부고시_CMR!$B:$J,8,FALSE),"제품 생식독성물질",""),""))),"") | BY8: =IFERROR(VLOOKUP(표1[[#This Row],[CAS No.]],[1]규제DB_위험물안전관리법_위험물!$B:$F,3,FALSE),"") | CB8: =IFERROR(IF(표1[[#This Row],[CAS No.]]=VLOOKUP(표1[[#This Row],[CAS No.]],[1]규제DB_고압법_특수고압가스!$B:$D,1,FALSE),"특수고압가스",""),"") | CC8: =IFERROR(IF(표1[[#This Row],[CAS No.]]=VLOOKUP(표1[[#This Row],[CAS No.]],[1]규제DB_고압법_특정고압가스!$B:$D,1,FALSE),"특정고압가스",""),"") | CD8: =IFERROR(IF(표1[[#This Row],[함량(W%)]]>=VLOOKUP(표1[[#This Row],[CAS No.]],[1]규제DB_화관법_개별취급기준!$B:$G,5,FALSE),VLOOKUP(표1[[#This Row],[CAS No.]],[1]규제DB_화관법_개별취급기준!$B:$G,6,FALSE),""),"")
A9: 8 | C9: 삼화당피앤티 | E9: soocoat av-208mf | F9: 내자 | G9: O | H9: 윤전 | I9: 인쇄 | J9: ㈜수케미칼 | K9: ㈜수케미칼 | M9: 원부자재 | N9: 옵셋 윤전 인쇄용 | O9: 혼합물 | P9: 액체 | Q9: 2800 | R9: 2800 | U9: 2800 | V9: 2800 | W9: =표1[[#This Row],[자재코드]]&"_"&표1[[#This Row],[자재명]]&"_"&표1[[#This Row],[공급업체명]] -> _soocoat av-208mf_㈜수케미칼 | X9: 물(WATER) | AB9: 50 | AC9: 코팅제 | AD9: X | AE9: O | AF9: O | AH9: 7732-18-5 | AI9: =IFERROR(표1[[#This Row],[사용량(kg)]]*표1[[#This Row],[함량(W%)]]/100,"") -> 1400 | AR9: =IFERROR(IF(표1[[#This Row],[함량(W%)]]>=VLOOKUP(표1[[#This Row],[CAS No.]],[1]규제DB_유해법_유독물!B:F,5,FALSE),"유독물질 제품",""),"") | AS9: =IFERROR(VLOOKUP(표1[[#This Row],[CAS No.]],[1]규제DB_유해법_금지물질!B:G,3,FALSE),"") | AT9: =IFERROR(VLOOKUP(표1[[#This Row],[CAS No.]],[1]규제DB_유해법_금지물질!B:G,4,FALSE)&" 인지 확인하세요","") | AU9: =IFERROR(VLOOKUP(표1[[#This Row],[CAS No.]],[1]규제DB_유해법_제한물질!B:G,3,FALSE),"") | AV9: =IFERROR(IF(표1[[#This Row],[함량(W%)]]>=VLOOKUP(표1[[#This Row],[CAS No.]],[1]규제DB_유해법_제한물질!$B:$G,5,FALSE),"제한 제품",""),"") | BA9: =IFERROR(IF(표1[[#This Row],[함량(W%)]]>=VLOOKUP(표1[[#This Row],[CAS No.]],[1]규제DB_유해법_사고대비물질!$B:$J,4,FALSE),VLOOKUP(표1[[#This Row],[CAS No.]],[1]규제DB_유해법_사고대비물질!$B$2:$J$70,7,FALSE),""),"") | BB9: =IFERROR(IF(표1[[#This Row],[함량(W%)]]>=VLOOKUP(표1[[#This Row],[CAS No.]],[1]규제DB_유해법_사고대비물질!$B:$J,4,FALSE),VLOOKUP(표1[[#This Row],[CAS No.]],[1]규제DB_유해법_사고대비물질!$B$2:$J$70,8,FALSE),""),"") | BC9: =IFERROR(IF(표1[[#This Row],[함량(W%)]]>=VLOOKUP(표1[[#This Row],[CAS No.]],[1]규제DB_유해법_사고대비물질!$B:$J,4,FALSE),VLOOKUP(표1[[#This Row],[CAS No.]],[1]규제DB_유해법_사고대비물질!$B$2:$J$70,9,FALSE),""),"") | BD9: =IFERROR(IF(표1[[#This Row],[함량(W%)]]>=VLOOKUP(표1[[#This Row],[CAS No.]],'[1]규제DB_유해법_배출량조사 I'!$B:$D,3,FALSE),IF(VLOOKUP(표1[[#This Row],[CAS No.]],[1]기초자료!$A:$C,3,FALSE)>=1000,"배출량조사 I 물질",""),""),"") | BF9: =IFERROR(IF(표1[[#This Row],[함량(W%)]]>=VLOOKUP(표1[[#This Row],[CAS No.]],[1]규제DB_산안법_금지물질!$B:$E,4,FALSE), VLOOKUP(표1[[#This Row],[CAS No.]],[1]규제DB_산안법_금지물질!$B:$E,2,FALSE)&" : "&VLOOKUP(표1[[#This Row],[CAS No.]],[1]규제DB_산안법_금지물질!$B:$E,3,FALSE)&" 인지 확인하세요",""),"") | BG9: =IFERROR(IF(표1[[#This Row],[함량(W%)]]>=VLOOKUP(표1[[#This Row],[CAS No.]],[1]규제DB_산안법_허가물질!$B:$E,4,FALSE), "제품 허가물질",""),"") | BH9: =IFERROR(IF(표1[[#This Row],[함량(W%)]]>=VLOOKUP(표1[[#This Row],[CAS No.]], [1]규제DB_산안법_특별관리물질!$B:$E,4,FALSE), "제품 특별관리물질",""),"") | BJ9: =IFERROR(IF(표1[[#This Row],[CAS No.]]=VLOOKUP(표1[[#This Row],[CAS No.]], [1]규제DB_산안법_허용기준이하물질!$B:$D,1,FALSE),"제품 허용기준이하물질",""),"") | BK9: =IFERROR(VLOOKUP(표1[[#This Row],[CAS No.]], [1]규제DB_산안법_허용기준이하물질!$B:$D,3,FALSE),"") | BQ9: =IFERROR(VLOOKUP(표1[[#This Row],[CAS No.]], [1]규제DB_산안법_노출기준설정물질!$B:$K,8,FALSE),"") | BR9: =IFERROR(VLOOKUP(표1[[#This Row],[CAS No.]], [1]규제DB_산안법_노출기준설정물질!$B:$K,9,FALSE),"") | BS9: =IFERROR(VLOOKUP(표1[[#This Row],[CAS No.]], [1]규제DB_산안법_노출기준설정물질!$B:$K,10,FALSE),"") | BV9: =IFERROR(IF(VLOOKUP(표1[[#This Row],[CAS No.]],[1]규제DB_고용노동부고시_CMR!$B:$J,3,FALSE)="구분1A", IF(표1[[#This Row],[함량(W%)]]>=VLOOKUP(표1[[#This Row],[CAS No.]],[1]규제DB_고용노동부고시_CMR!$B:$J,4,FALSE),"제품 발암성물질",""), IF(VLOOKUP(표1[[#This Row],[CAS No.]],[1]규제DB_고용노동부고시_CMR!$B:$J,3,FALSE)="구분1B", IF(표1[[#This Row],[함량(W%)]]>=VLOOKUP(표1[[#This Row],[CAS No.]],[1]규제DB_고용노동부고시_CMR!$B:$J,4,FALSE),"제품 발암성물질",""), IF(VLOOKUP(표1[[#This Row],[CAS No.]],[1]규제DB_고용노동부고시_CMR!$B:$J,3,FALSE)="구분2", IF(표1[[#This Row],[함량(W%)]]>=VLOOKUP(표1[[#This Row],[CAS No.]],[1]규제DB_고용노동부고시_CMR!$B:$J,4,FALSE),"제품 발암성물질",""),""))),"") | BW9: =IFERROR(IF(VLOOKUP(표1[[#This Row],[CAS No.]],[1]규제DB_고용노동부고시_CMR!$B:$J,5,FALSE)="구분1A", IF(표1[[#This Row],[함량(W%)]]>=VLOOKUP(표1[[#This Row],[CAS No.]],[1]규제DB_고용노동부고시_CMR!$B:$J,6,FALSE),"제품 생식세포변이원성물질",""), IF(VLOOKUP(표1[[#This Row],[CAS No.]],[1]규제DB_고용노동부고시_CMR!$B:$J,5,FALSE)="구분1B", IF(표1[[#This Row],[함량(W%)]]>=VLOOKUP(표1[[#This Row],[CAS No.]],[1]규제DB_고용노동부고시_CMR!$B:$J,6,FALSE),"제품 생식세포변이원성물질",""), IF(VLOOKUP(표1[[#This Row],[CAS No.]],[1]규제DB_고용노동부고시_CMR!$B:$J,5,FALSE)="구분2", IF(표1[[#This Row],[함량(W%)]]>=VLOOKUP(표1[[#This Row],[CAS No.]],[1]규제DB_고용노동부고시_CMR!$B:$J,6,FALSE),"제품 생식세포변이원성물질",""),""))),"") | BX9: =IFERROR(IF(VLOOKUP(표1[[#This Row],[CAS No.]],[1]규제DB_고용노동부고시_CMR!$B:$J,7,FALSE)="구분1A", IF(표1[[#This Row],[함량(W%)]]>=VLOOKUP(표1[[#This Row],[CAS No.]],[1]규제DB_고용노동부고시_CMR!$B:$J,8,FALSE),"제품 생식독성물질",""), IF(VLOOKUP(표1[[#This Row],[CAS No.]],[1]규제DB_고용노동부고시_CMR!$B:$J,7,FALSE)="구분1B", IF(표1[[#This Row],[함량(W%)]]>=VLOOKUP(표1[[#This Row],[CAS No.]],[1]규제DB_고용노동부고시_CMR!$B:$J,8,FALSE),"제품 생식독성물질",""), IF(VLOOKUP(표1[[#This Row],[CAS No.]],[1]규제DB_고용노동부고시_CMR!$B:$J,7,FALSE)="구분2", IF(표1[[#This Row],[함량(W%)]]>=VLOOKUP(표1[[#This Row],[CAS No.]],[1]규제DB_고용노동부고시_CMR!$B:$J,8,FALSE),"제품 생식독성물질",""),""))),"") | BY9: =IFERROR(VLOOKUP(표1[[#This Row],[CAS No.]],[1]규제DB_위험물안전관리법_위험물!$B:$F,3,FALSE),"") | BZ9: =IFERROR(IF(표1[[#This Row],[CAS No.]]=VLOOKUP(표1[[#This Row],[CAS No.]],[1]규제DB_고압법_독성가스!$B:$D,1,FALSE),"독성가스",""),"") | CA9: =IFERROR(IF(표1[[#This Row],[CAS No.]]=VLOOKUP(표1[[#This Row],[CAS No.]],[1]규제DB_고압법_가연성가스!$B:$D,1,FALSE),"가연성가스",""),"") | CB9: =IFERROR(IF(표1[[#This Row],[CAS No.]]=VLOOKUP(표1[[#This Row],[CAS No.]],[1]규제DB_고압법_특수고압가스!$B:$D,1,FALSE),"특수고압가스",""),"") | CC9: =IFERROR(IF(표1[[#This Row],[CAS No.]]=VLOOKUP(표1[[#This Row],[CAS No.]],[1]규제DB_고압법_특정고압가스!$B:$D,1,FALSE),"특정고압가스",""),"") | CD9: =IFERROR(IF(표1[[#This Row],[함량(W%)]]>=VLOOKUP(표1[[#This Row],[CAS No.]],[1]규제DB_화관법_개별취급기준!$B:$G,5,FALSE),VLOOKUP(표1[[#This Row],[CAS No.]],[1]규제DB_화관법_개별취급기준!$B:$G,6,FALSE),""),"")
A10: 9 | C10: 삼화당피앤티 | E10: soocoat av-208mf | F10: 내자 | G10: O | H10: 윤전 | I10: 인쇄 | J10: ㈜수케미칼 | K10: ㈜수케미칼 | M10: 원부자재 | N10: 옵셋 윤전 인쇄용 | O10: 혼합물 | P10: 액체 | Q10: 2800 | R10: 2800 | U10: 2800 | V10: 2800 | W10: =표1[[#This Row],[자재코드]]&"_"&표1[[#This Row],[자재명]]&"_"&표1[[#This Row],[공급업체명]] -> _soocoat av-208mf_㈜수케미칼 | X10: 이소프로필 알코올 | AB10: 1.6 | AC10: 코팅제 | AD10: X | AE10: O | AF10: O | AH10: 67-63-0 | AI10: =IFERROR(표1[[#This Row],[사용량(kg)]]*표1[[#This Row],[함량(W%)]]/100,"") -> 44.8 | AR10: =IFERROR(IF(표1[[#This Row],[함량(W%)]]>=VLOOKUP(표1[[#This Row],[CAS No.]],[1]규제DB_유해법_유독물!B:F,5,FALSE),"유독물질 제품",""),"") | AS10: =IFERROR(VLOOKUP(표1[[#This Row],[CAS No.]],[1]규제DB_유해법_금지물질!B:G,3,FALSE),"") | AT10: =IFERROR(VLOOKUP(표1[[#This Row],[CAS No.]],[1]규제DB_유해법_금지물질!B:G,4,FALSE)&" 인지 확인하세요","") | AU10: =IFERROR(VLOOKUP(표1[[#This Row],[CAS No.]],[1]규제DB_유해법_제한물질!B:G,3,FALSE),"") | AV10: =IFERROR(IF(표1[[#This Row],[함량(W%)]]>=VLOOKUP(표1[[#This Row],[CAS No.]],[1]규제DB_유해법_제한물질!$B:$G,5,FALSE),"제한 제품",""),"") | BA10: =IFERROR(IF(표1[[#This Row],[함량(W%)]]>=VLOOKUP(표1[[#This Row],[CAS No.]],[1]규제DB_유해법_사고대비물질!$B:$J,4,FALSE),VLOOKUP(표1[[#This Row],[CAS No.]],[1]규제DB_유해법_사고대비물질!$B$2:$J$70,7,FALSE),""),"") | BB10: =IFERROR(IF(표1[[#This Row],[함량(W%)]]>=VLOOKUP(표1[[#This Row],[CAS No.]],[1]규제DB_유해법_사고대비물질!$B:$J,4,FALSE),VLOOKUP(표1[[#This Row],[CAS No.]],[1]규제DB_유해법_사고대비물질!$B$2:$J$70,8,FALSE),""),"") | BC10: =IFERROR(IF(표1[[#This Row],[함량(W%)]]>=VLOOKUP(표1[[#This Row],[CAS No.]],[1]규제DB_유해법_사고대비물질!$B:$J,4,FALSE),VLOOKUP(표1[[#This Row],[CAS No.]],[1]규제DB_유해법_사고대비물질!$B$2:$J$70,9,FALSE),""),"") | BD10: =IFERROR(IF(표1[[#This Row],[함량(W%)]]>=VLOOKUP(표1[[#This Row],[CAS No.]],'[1]규제DB_유해법_배출량조사 I'!$B:$D,3,FALSE),IF(VLOOKUP(표1[[#This Row],[CAS No.]],[1]기초자료!$A:$C,3,FALSE)>=1000,"배출량조사 I 물질",""),""),"") | BF10: =IFERROR(IF(표1[[#This Row],[함량(W%)]]>=VLOOKUP(표1[[#This Row],[CAS No.]],[1]규제DB_산안법_금지물질!$B:$E,4,FALSE), VLOOKUP(표1[[#This Row],[CAS No.]],[1]규제DB_산안법_금지물질!$B:$E,2,FALSE)&" : "&VLOOKUP(표1[[#This Row],[CAS No.]],[1]규제DB_산안법_금지물질!$B:$E,3,FALSE)&" 인지 확인하세요",""),"") | BG10: =IFERROR(IF(표1[[#This Row],[함량(W%)]]>=VLOOKUP(표1[[#This Row],[CAS No.]],[1]규제DB_산안법_허가물질!$B:$E,4,FALSE), "제품 허가물질",""),"") | BH10: =IFERROR(IF(표1[[#This Row],[함량(W%)]]>=VLOOKUP(표1[[#This Row],[CAS No.]], [1]규제DB_산안법_특별관리물질!$B:$E,4,FALSE), "제품 특별관리물질",""),"") | BJ10: =IFERROR(IF(표1[[#This Row],[CAS No.]]=VLOOKUP(표1[[#This Row],[CAS No.]], [1]규제DB_산안법_허용기준이하물질!$B:$D,1,FALSE),"제품 허용기준이하물질",""),"") | BK10: =IFERROR(VLOOKUP(표1[[#This Row],[CAS No.]], [1]규제DB_산안법_허용기준이하물질!$B:$D,3,FALSE),"") | BQ10: =IFERROR(VLOOKUP(표1[[#This Row],[CAS No.]], [1]규제DB_산안법_노출기준설정물질!$B:$K,8,FALSE),"") | BR10: =IFERROR(VLOOKUP(표1[[#This Row],[CAS No.]], [1]규제DB_산안법_노출기준설정물질!$B:$K,9,FALSE),"") | BS10: =IFERROR(VLOOKUP(표1[[#This Row],[CAS No.]], [1]규제DB_산안법_노출기준설정물질!$B:$K,10,FALSE),"") | BV10: =IFERROR(IF(VLOOKUP(표1[[#This Row],[CAS No.]],[1]규제DB_고용노동부고시_CMR!$B:$J,3,FALSE)="구분1A", IF(표1[[#This Row],[함량(W%)]]>=VLOOKUP(표1[[#This Row],[CAS No.]],[1]규제DB_고용노동부고시_CMR!$B:$J,4,FALSE),"제품 발암성물질",""), IF(VLOOKUP(표1[[#This Row],[CAS No.]],[1]규제DB_고용노동부고시_CMR!$B:$J,3,FALSE)="구분1B", IF(표1[[#This Row],[함량(W%)]]>=VLOOKUP(표1[[#This Row],[CAS No.]],[1]규제DB_고용노동부고시_CMR!$B:$J,4,FALSE),"제품 발암성물질",""), IF(VLOOKUP(표1[[#This Row],[CAS No.]],[1]규제DB_고용노동부고시_CMR!$B:$J,3,FALSE)="구분2", IF(표1[[#This Row],[함량(W%)]]>=VLOOKUP(표1[[#This Row],[CAS No.]],[1]규제DB_고용노동부고시_CMR!$B:$J,4,FALSE),"제품 발암성물질",""),""))),"") | BW10: =IFERROR(IF(VLOOKUP(표1[[#This Row],[CAS No.]],[1]규제DB_고용노동부고시_CMR!$B:$J,5,FALSE)="구분1A", IF(표1[[#This Row],[함량(W%)]]>=VLOOKUP(표1[[#This Row],[CAS No.]],[1]규제DB_고용노동부고시_CMR!$B:$J,6,FALSE),"제품 생식세포변이원성물질",""), IF(VLOOKUP(표1[[#This Row],[CAS No.]],[1]규제DB_고용노동부고시_CMR!$B:$J,5,FALSE)="구분1B", IF(표1[[#This Row],[함량(W%)]]>=VLOOKUP(표1[[#This Row],[CAS No.]],[1]규제DB_고용노동부고시_CMR!$B:$J,6,FALSE),"제품 생식세포변이원성물질",""), IF(VLOOKUP(표1[[#This Row],[CAS No.]],[1]규제DB_고용노동부고시_CMR!$B:$J,5,FALSE)="구분2", IF(표1[[#This Row],[함량(W%)]]>=VLOOKUP(표1[[#This Row],[CAS No.]],[1]규제DB_고용노동부고시_CMR!$B:$J,6,FALSE),"제품 생식세포변이원성물질",""),""))),"") | BX10: =IFERROR(IF(VLOOKUP(표1[[#This Row],[CAS No.]],[1]규제DB_고용노동부고시_CMR!$B:$J,7,FALSE)="구분1A", IF(표1[[#This Row],[함량(W%)]]>=VLOOKUP(표1[[#This Row],[CAS No.]],[1]규제DB_고용노동부고시_CMR!$B:$J,8,FALSE),"제품 생식독성물질",""), IF(VLOOKUP(표1[[#This Row],[CAS No.]],[1]규제DB_고용노동부고시_CMR!$B:$J,7,FALSE)="구분1B", IF(표1[[#This Row],[함량(W%)]]>=VLOOKUP(표1[[#This Row],[CAS No.]],[1]규제DB_고용노동부고시_CMR!$B:$J,8,FALSE),"제품 생식독성물질",""), IF(VLOOKUP(표1[[#This Row],[CAS No.]],[1]규제DB_고용노동부고시_CMR!$B:$J,7,FALSE)="구분2", IF(표1[[#This Row],[함량(W%)]]>=VLOOKUP(표1[[#This Row],[CAS No.]],[1]규제DB_고용노동부고시_CMR!$B:$J,8,FALSE),"제품 생식독성물질",""),""))),"") | BZ10: =IFERROR(IF(표1[[#This Row],[CAS No.]]=VLOOKUP(표1[[#This Row],[CAS No.]],[1]규제DB_고압법_독성가스!$B:$D,1,FALSE),"독성가스",""),"") | CA10: =IFERROR(IF(표1[[#This Row],[CAS No.]]=VLOOKUP(표1[[#This Row],[CAS No.]],[1]규제DB_고압법_가연성가스!$B:$D,1,FALSE),"가연성가스",""),"") | CB10: =IFERROR(IF(표1[[#This Row],[CAS No.]]=VLOOKUP(표1[[#This Row],[CAS No.]],[1]규제DB_고압법_특수고압가스!$B:$D,1,FALSE),"특수고압가스",""),"") | CC10: =IFERROR(IF(표1[[#This Row],[CAS No.]]=VLOOKUP(표1[[#This Row],[CAS No.]],[1]규제DB_고압법_특정고압가스!$B:$D,1,FALSE),"특정고압가스",""),"") | CD10: =IFERROR(IF(표1[[#This Row],[함량(W%)]]>=VLOOKUP(표1[[#This Row],[CAS No.]],[1]규제DB_화관법_개별취급기준!$B:$G,5,FALSE),VLOOKUP(표1[[#This Row],[CAS No.]],[1]규제DB_화관법_개별취급기준!$B:$G,6,FALSE),""),"")
A11: 10 | C11: 삼화당피앤티 | E11: dh-237 | F11: 내자 | G11: O | H11: 접착 | I11: 접착 | J11: 대현화학 | K11: 대현화학 | M11: 원부자재 | N11: 접착 장비용 접착제 | O11: 혼합물 | P11: 고체 | Q11: 200 | R11: 200 | U11: 200 | V11: 200 | W11: =표1[[#This Row],[자재코드]]&"_"&표1[[#This Row],[자재명]]&"_"&표1[[#This Row],[공급업체명]] -> _dh-237_대현화학 | X11: 스타이렌-부타디엔 고무(STYRENE-BUTADIENE RUBBER) | AB11: 5 | AC11: 주성분 | AD11: X | AE11: O | AF11: O | AH11: 9003-55-8 | AI11: =IFERROR(표1[[#This Row],[사용량(kg)]]*표1[[#This Row],[함량(W%)]]/100,"") -> 10 | AR11: =IFERROR(IF(표1[[#This Row],[함량(W%)]]>=VLOOKUP(표1[[#This Row],[CAS No.]],[1]규제DB_유해법_유독물!B:F,5,FALSE),"유독물질 제품",""),"") | AS11: =IFERROR(VLOOKUP(표1[[#This Row],[CAS No.]],[1]규제DB_유해법_금지물질!B:G,3,FALSE),"") | AT11: =IFERROR(VLOOKUP(표1[[#This Row],[CAS No.]],[1]규제DB_유해법_금지물질!B:G,4,FALSE)&" 인지 확인하세요","") | AU11: =IFERROR(VLOOKUP(표1[[#This Row],[CAS No.]],[1]규제DB_유해법_제한물질!B:G,3,FALSE),"") | AV11: =IFERROR(IF(표1[[#This Row],[함량(W%)]]>=VLOOKUP(표1[[#This Row],[CAS No.]],[1]규제DB_유해법_제한물질!$B:$G,5,FALSE),"제한 제품",""),"") | BA11: =IFERROR(IF(표1[[#This Row],[함량(W%)]]>=VLOOKUP(표1[[#This Row],[CAS No.]],[1]규제DB_유해법_사고대비물질!$B:$J,4,FALSE),VLOOKUP(표1[[#This Row],[CAS No.]],[1]규제DB_유해법_사고대비물질!$B$2:$J$70,7,FALSE),""),"") | BB11: =IFERROR(IF(표1[[#This Row],[함량(W%)]]>=VLOOKUP(표1[[#This Row],[CAS No.]],[1]규제DB_유해법_사고대비물질!$B:$J,4,FALSE),VLOOKUP(표1[[#This Row],[CAS No.]],[1]규제DB_유해법_사고대비물질!$B$2:$J$70,8,FALSE),""),"") | BC11: =IFERROR(IF(표1[[#This Row],[함량(W%)]]>=VLOOKUP(표1[[#This Row],[CAS No.]],[1]규제DB_유해법_사고대비물질!$B:$J,4,FALSE),VLOOKUP(표1[[#This Row],[CAS No.]],[1]규제DB_유해법_사고대비물질!$B$2:$J$70,9,FALSE),""),"") | BD11: =IFERROR(IF(표1[[#This Row],[함량(W%)]]>=VLOOKUP(표1[[#This Row],[CAS No.]],'[1]규제DB_유해법_배출량조사 I'!$B:$D,3,FALSE),IF(VLOOKUP(표1[[#This Row],[CAS No.]],[1]기초자료!$A:$C,3,FALSE)>=1000,"배출량조사 I 물질",""),""),"") | BF11: =IFERROR(IF(표1[[#This Row],[함량(W%)]]>=VLOOKUP(표1[[#This Row],[CAS No.]],[1]규제DB_산안법_금지물질!$B:$E,4,FALSE), VLOOKUP(표1[[#This Row],[CAS No.]],[1]규제DB_산안법_금지물질!$B:$E,2,FALSE)&" : "&VLOOKUP(표1[[#This Row],[CAS No.]],[1]규제DB_산안법_금지물질!$B:$E,3,FALSE)&" 인지 확인하세요",""),"") | BG11: =IFERROR(IF(표1[[#This Row],[함량(W%)]]>=VLOOKUP(표1[[#This Row],[CAS No.]],[1]규제DB_산안법_허가물질!$B:$E,4,FALSE), "제품 허가물질",""),"") | BH11: =IFERROR(IF(표1[[#This Row],[함량(W%)]]>=VLOOKUP(표1[[#This Row],[CAS No.]], [1]규제DB_산안법_특별관리물질!$B:$E,4,FALSE), "제품 특별관리물질",""),"") | BJ11: =IFERROR(IF(표1[[#This Row],[CAS No.]]=VLOOKUP(표1[[#This Row],[CAS No.]], [1]규제DB_산안법_허용기준이하물질!$B:$D,1,FALSE),"제품 허용기준이하물질",""),"") | BK11: =IFERROR(VLOOKUP(표1[[#This Row],[CAS No.]], [1]규제DB_산안법_허용기준이하물질!$B:$D,3,FALSE),"") | BQ11: =IFERROR(VLOOKUP(표1[[#This Row],[CAS No.]], [1]규제DB_산안법_노출기준설정물질!$B:$K,8,FALSE),"") | BR11: =IFERROR(VLOOKUP(표1[[#This Row],[CAS No.]], [1]규제DB_산안법_노출기준설정물질!$B:$K,9,FALSE),"") | BS11: =IFERROR(VLOOKUP(표1[[#This Row],[CAS No.]], [1]규제DB_산안법_노출기준설정물질!$B:$K,10,FALSE),"") | BV11: =IFERROR(IF(VLOOKUP(표1[[#This Row],[CAS No.]],[1]규제DB_고용노동부고시_CMR!$B:$J,3,FALSE)="구분1A", IF(표1[[#This Row],[함량(W%)]]>=VLOOKUP(표1[[#This Row],[CAS No.]],[1]규제DB_고용노동부고시_CMR!$B:$J,4,FALSE),"제품 발암성물질",""), IF(VLOOKUP(표1[[#This Row],[CAS No.]],[1]규제DB_고용노동부고시_CMR!$B:$J,3,FALSE)="구분1B", IF(표1[[#This Row],[함량(W%)]]>=VLOOKUP(표1[[#This Row],[CAS No.]],[1]규제DB_고용노동부고시_CMR!$B:$J,4,FALSE),"제품 발암성물질",""), IF(VLOOKUP(표1[[#This Row],[CAS No.]],[1]규제DB_고용노동부고시_CMR!$B:$J,3,FALSE)="구분2", IF(표1[[#This Row],[함량(W%)]]>=VLOOKUP(표1[[#This Row],[CAS No.]],[1]규제DB_고용노동부고시_CMR!$B:$J,4,FALSE),"제품 발암성물질",""),""))),"") | BW11: =IFERROR(IF(VLOOKUP(표1[[#This Row],[CAS No.]],[1]규제DB_고용노동부고시_CMR!$B:$J,5,FALSE)="구분1A", IF(표1[[#This Row],[함량(W%)]]>=VLOOKUP(표1[[#This Row],[CAS No.]],[1]규제DB_고용노동부고시_CMR!$B:$J,6,FALSE),"제품 생식세포변이원성물질",""), IF(VLOOKUP(표1[[#This Row],[CAS No.]],[1]규제DB_고용노동부고시_CMR!$B:$J,5,FALSE)="구분1B", IF(표1[[#This Row],[함량(W%)]]>=VLOOKUP(표1[[#This Row],[CAS No.]],[1]규제DB_고용노동부고시_CMR!$B:$J,6,FALSE),"제품 생식세포변이원성물질",""), IF(VLOOKUP(표1[[#This Row],[CAS No.]],[1]규제DB_고용노동부고시_CMR!$B:$J,5,FALSE)="구분2", IF(표1[[#This Row],[함량(W%)]]>=VLOOKUP(표1[[#This Row],[CAS No.]],[1]규제DB_고용노동부고시_CMR!$B:$J,6,FALSE),"제품 생식세포변이원성물질",""),""))),"") | BZ11: =IFERROR(IF(표1[[#This Row],[CAS No.]]=VLOOKUP(표1[[#This Row],[CAS No.]],[1]규제DB_고압법_독성가스!$B:$D,1,FALSE),"독성가스",""),"") | CA11: =IFERROR(IF(표1[[#This Row],[CAS No.]]=VLOOKUP(표1[[#This Row],[CAS No.]],[1]규제DB_고압법_가연성가스!$B:$D,1,FALSE),"가연성가스",""),"") | CB11: =IFERROR(IF(표1[[#This Row],[CAS No.]]=VLOOKUP(표1[[#This Row],[CAS No.]],[1]규제DB_고압법_특수고압가스!$B:$D,1,FALSE),"특수고압가스",""),"") | CC11: =IFERROR(IF(표1[[#This Row],[CAS No.]]=VLOOKUP(표1[[#This Row],[CAS No.]],[1]규제DB_고압법_특정고압가스!$B:$D,1,FALSE),"특정고압가스",""),"") | CD11: =IFERROR(IF(표1[[#This Row],[함량(W%)]]>=VLOOKUP(표1[[#This Row],[CAS No.]],[1]규제DB_화관법_개별취급기준!$B:$G,5,FALSE),VLOOKUP(표1[[#This Row],[CAS No.]],[1]규제DB_화관법_개별취급기준!$B:$G,6,FALSE),""),"")
