Workbook
Name _: #REF!
Name _: #REF!
Name _: #REF!
Name _: #REF!
Name _: #REF!
Name _?쨲?f: #REF!
Name _?쨲?f: #REF!
Name _?쨲?f: #REF!
Name _1: #REF!
Name _1: #REF!
Name _1: #REF!
Name _1_0: [1]Sheet1!#REF!
Name _1_0: [1]Sheet1!#REF!
Name _1_0: [1]Sheet1!#REF!
Name _2: #REF!
Name _2: #REF!
Name _2: #REF!
Name _2: #REF!
Name _2: #REF!
Name _2_0: '[2]TNC(1안)'!#REF!
Name _2_0: '[2]TNC(1안)'!#REF!
Name _2_0: '[2]TNC(1안)'!#REF!
Name _2_0: '[2]TNC(1안)'!#REF!
Name _2_0: '[2]TNC(1안)'!#REF!
Name _3_0사업장: [1]Sheet1!#REF!
Name _3_0사업장: [1]Sheet1!#REF!
Name _3_0사업장: [1]Sheet1!#REF!
Name _3_0사업장: [1]Sheet1!#REF!
Name _4_0원가: [1]Sheet1!#REF!
Name _4_0원가: [1]Sheet1!#REF!
Name _4_0원가: [1]Sheet1!#REF!
Name _5a2_: #REF!
Name _5a2_: #REF!
Name _5a2_: #REF!
Name _5a2_: #REF!
Name _5a2_: #REF!
Name _9연봉입력: #REF!
Name _9연봉입력: #REF!
Name _9연봉입력: #REF!
Name _aof2: #REF!
Name _aof2: #REF!
Name _aof2: #REF!
Name _PRT1: #REF!
Name _PRT1: #REF!
Name _PRT1: #REF!
Name _PRT1: #REF!
Name _PRT1: #REF!
Name ´e±¸: [4]대구!$I$10:$K$48
Name ¿e¿￢: [4]용연!$I$10:$K$48
Name ¿i≫e: [4]울산!$I$10:$K$125
Name ¿ø°¡: '[4]#REF'!#REF!
Name ¿ø°¡: '[4]#REF'!#REF!
Name ¿ø°¡: '[4]#REF'!#REF!
Name ¿ø°¡: '[4]#REF'!#REF!
Name ¿ø°¡: '[4]#REF'!#REF!
Name ¿ø°¡Ay°¨: '[4]#REF'!#REF!
Name ¿ø°¡Ay°¨: '[4]#REF'!#REF!
Name ¿ø°¡Ay°¨: '[4]#REF'!#REF!
Name ¿ø°¡Ay°¨: '[4]#REF'!#REF!
Name \a: '[5]#REF'!$B$47:$C$56

Sheet Cover
A1: 기후변화 대응을 위한 공급사 현황 조사표
A3: A. 배경
A4: 현재 국제사회는 기후변화에 대응하기 위한 포괄적 정책 방향으로 ‘탄소중립(carbon neutrality)’을 선언하고, 온실가스 감축정책을 적극적으로 추진하고 있습니다.
A6: 파리협정(Paris Agreement)의 지구온난화 완화 목표인 ‘2100년까지 지구 평균온도 상승을 산업화 이전 대비 2℃ 이하로 제한’을 달성하기 위해서는 현재보다 상향된 온실가스 감축 노력이 필요하며, 이러한 맥락에서 국제사회는 탄소중립 2050년 탄소중립 목표에 주목하고 있으며, 많은 기업들이 이보다 앞서 탄소중립에 대한 목표를 수립하고 대응하고 있습니다.
A9: 이러한 측면에서 기후변화 대응은 삼성바이오로직의 제품과 서비스부터 제조공정, 공급망, 연구개발, 그외 여러 경영활동에 영향을 미치므로 각각의 기후변화 리스크와 기회요인 분석이 필요합니다.
A12: B. 목적
A13: ㈜삼화당피앤티는 기후변화 대응을 위해 재생에너지로의 전환, 운송부문 배출량 상쇄등 여러 핵심활동을 우선 실행 범위로 설정하였습니다. 내부적 노력을 기울이는 과정에서 글로벌 차원에서 상호 협력할 때 더 큰 영향력을 발휘할 수 있음을 또한 인식하게 되었습니다.
A15: ㈜삼화당피앤티는 기후변화 위험과 기회를 분석하고 효과적인 대응 전략을 수립하였습니다. 사업 전반에 걸쳐 배출하는 온실가스 배출의 3가지 범주인 Scope 1, 2, 3를 면밀히 파악하고 관리하는 것은 기후변화 대응을 위한 ㈜삼화당피앤티의 기본적 목표입니다.
A35: ※ Scope1, Scope2, Scope3 정의
A36: Scope1 : 사업장에서 밸생되는 직접 배출량
A37: → 사업자가 직접적으로 소유하고 통제하는 사업장내에서 운영 및 활동에 관계되어 온실가스가 직접적으로 배출되는 배출원
A38: Scope2 : 사업장이 소비하는 전기, 증기, 난방 및 냉방을 구매한 전기, 증기, 냉난방 발전으로 인한 간접 배출량
... A42: 본 조사표는 Scope3 배출 협력사 물품 공급 단계에 해당하는 '구매한 제품 및 서비스'에 해당되는 범주를 조사하고자 작성되었으며, 자료의 출저는 Greenhouse gas protocol에서 발간한 'Technical Guidance For Calculating Scope 3 Emissions (version 1.0)' 가이드를 기준으로 작성하였습니다.
B48: 회사명 | C48: ㈜삼화당피앤티
B49: 국적 | C49: 대한민국
B50: 주소 | C50: 경기도 남양주시 진건읍 진관산단로59번길 39
B51: 담당자 | C51: 소속 | D51: 연구소 | E51: 성명 | F51: 김 기 태
C52: 전화번호 | D52: 02- 464- 3752 | E52: Email | F52: ktkim@samhwadang.co.kr
A54: 2025.1
D56: ㈜삼화당피앤티

Sheet KPI(성과지표)그래프
A1: 주요 KPI(Key Performance Index) 월별 추이분석
A3: KPI(성과지표) 그래프
A5: 1. 원단 로스 수율(%)
A6: 모니터링 기준 | C6: 원단 로스 수율(%)
A7: 계산방법 | C7: 실제사용수량(수율 % )
A9: 구분 | B9: 2023년下 | C9: 2024년 | D9: 평균 | E9: 1월 | F9: 2월 | G9: 3월 | H9: 4월 | I9: 5월 | J9: 6월 | K9: 7월 | L9: 8월 | M9: 9월 | N9: 10월 | O9: 11월
A10: 계획 | C10: 98 | D10: 98 | E10: 98 | F10: 98 | G10: 98 | H10: 98 | I10: 98 | J10: 98 | K10: 98 | L10: 98 | M10: 98 | N10: 98 | O10: 98
A11: 실적 | B11: 92.8 | C11: =D11 -> 93.2 | D11: =AVERAGE(E11:O11) -> 93.2 | E11: 94.8 | F11: 92 | G11: 91 | H11: 91 | I11: 94 | J11: 95 | K11: 94 | L11: 93.4 | M11: 92 | N11: 92 | O11: 96
A13: 2. 폐기물 마대 감소율
A14: 모니터링 기준 | C14: 사용 매수 (단원: EA)
A15: 계산방법 | C15: 실제 사용량
A17: 구분 | B17: 2023년下 | C17: 2024년 | D17: 평균 | E17: 1월 | F17: 2월 | G17: 3월 | H17: 4월 | I17: 5월 | J17: 6월 | K17: 7월 | L17: 8월 | M17: 9월 | N17: 10월 | O17: 11월
A18: 계획 | B18: 6 | C18: 6 | D18: 6 | E18: 6 | F18: 6 | G18: 6 | H18: 6 | I18: 6 | J18: 6 | K18: 6 | L18: 6 | M18: 6 | N18: 6 | O18: 6
A19: 실적 | B19: 4.6 | C19: =D19 -> 5 | D19: =AVERAGE(L19:O19) -> 5 | E19: 6 | F19: 4 | G19: 6 | H19: 6 | I19: 6 | J19: 4 | K19: 4 | L19: 4 | M19: 8 | N19: 4 | O19: 4
A21: 3. 전기소비량
A22: 모니터링 기준 | C22: 금액(단위 : 만원)
A23: 계산방법 | C23: 실제사용금액
A25: 구분 | B25: 2023년下 | C25: 2024년 | D25: 평균 | E25: 1월 | F25: 2월 | G25: 3월 | H25: 4월 | I25: 5월 | J25: 6월 | K25: 7월 | L25: 8월 | M25: 9월 | N25: 10월 | O25: 11월
A26: 계획 | C26: 600 | D26: 600 | E26: 600 | F26: 600 | G26: 600 | H26: 600 | I26: 600 | J26: 600 | K26: 600 | L26: 600 | M26: 600 | N26: 600 | O26: 600
A27: 실적 | B27: 703 | C27: =D27 -> 692.4 | D27: =AVERAGE(E27:O27) -> 692.4 | E27: 795 | F27: 774 | G27: 669 | H27: 639 | I27: 586 | J27: 764 | K27: 783 | L27: 691 | M27: 640 | N27: 583 | O27: N/A
A30: 4. 가스소비량
A31: 모니터링 기준 | C31: 금액(단위 : 만원)
A32: 계산방법 | C32: 실제사용금액
A34: 구분 | B34: 2023년下 | C34: 2024년 | D34: 평균 | E34: 1월 | F34: 2월 | G34: 3월 | H34: 4월 | I34: 5월 | J34: 6월 | K34: 7월 | L34: 8월 | M34: 9월 | N34: 10월 | O34: 11월
A35: 계획 | C35: 150 | D35: 150 | E35: 150 | F35: 150 | G35: 150 | H35: 150 | I35: 150 | J35: 150 | K35: 150 | L35: 150 | M35: 150 | N35: 150 | O35: 150
A36: 실적 | B36: 170 | C36: =D36 -> 173.5 | D36: =AVERAGE(E36:O36) -> 173.5 | E36: 360 | F36: 236 | G36: 168 | H36: 13 | I36: 57 | J36: 166 | K36: 244 | L36: 242 | M36: 193 | N36: 56 | O36: N/A
A39: 5. 상하수도소비량
A40: 모니터링 기준 | C40: 금액(단위 : 만원)
A41: 계산방법 | C41: 실제사용금액
A43: 구분 | B43: 2023년下 | C43: 2024년 | D43: 평균 | E43: 1월 | F43: 2월 | G43: 3월 | H43: 4월 | I43: 5월 | J43: 6월 | K43: 7월 | L43: 8월 | M43: 9월 | N43: 10월 | O43: 11월
A44: 계획 | C44: 12 | D44: 12 | E44: 12 | F44: 12 | G44: 12 | H44: 12 | I44: 12 | J44: 12 | K44: 12 | L44: 12 | M44: 12 | N44: 12 | O44: 12
A45: 실적 | B45: 14 | C45: =D45 -> 12 | D45: =AVERAGE(E45:O45) -> 12 | E45: 12 | F45: 11 | G45: 11 | H45: 11 | I45: 15 | J45: 8 | K45: 16 | L45: 13 | M45: 11 | N45: 12 | O45: N/A

Sheet 탄소배출량 계산근거자료 23년
A4: 2023년 배출량 계산
A7: 구분 | B7: 사용량 | C7: 온실가스배출량 (tco2/Kmw) | D7: 금액 | E7: scope | F7: 비고
A8: 전기 | B8: 474,944 KW | C8: 215 | D8: 76160000 | E8: scope2 | F8: 연간 전기 사용량(고지서)
A9: 가스사용량 | B9: 19,740 mJ | D9: 19866000 | E9: scope2 | F9: 연간 가스사용량(고지서)
A10: 상하수도사용량 | B10: 987 ton | D10: 1678000 | E10: scope2 | F10: 연간 상하수도사용량(고지서)
A12: 종량제 봉투 사용량 | B12: 4,500 리터(75리터 X 60개) | F12: 연간 총 사용량
A13: 음식물 쓰레기 사용량 | B13: 5KG X 20(일) X 12(개월)= 1,200KG | F13: 연간 총 사용량
A14: 폐기물 마대사용량 | B14: 72개 | F14: 연간 총 사용량
A15: 연간유해 폐기물량 | B15: 4,120 KG | F15: 업체 자료기준
A17: 연간 제품 운송 배출량 | B17: 15,772 리터 | C17: 41 | D17: 21500000 | E17: scope3 | F17: 연간 주유량(법인 차량2대)
A18: 출퇴근 시 소요 배출량 | B18: 13,500 리터 | C18: 35 | D18: 18500000 | E18: scope3 | F18: 전 직원 출퇴근거리 연간 주유량
A21: * 참고 자료
A23: 1. 에너지 온실 가스 종합정보 플랫폼
A24: https://tips.energy.or.kr/popup/toe.do
A70: 2. SCOPE3 측정 가이드 북 참고
A75: * Scope 3
A77: [ 원자재 입고전]
A78: 1. 카테고리: 원자재의 탄소 배출량
A79: 2. 카테고리: 생산에 사용되는 설비, 장비의 탄소배출량
A80: 3. 카테고리: 회사운영에 사용되는 연료를 채굴하고 운반하고 정제되는 과정에서 발생되는 탄소배출량
A81: 4. 카테고리: 우리회사에 필요한 원자재와 설비를 다른 회사에서 운송되는 과정에서 발생되는 탄소배출량
A83: [ 생산공정]
A84: 5. 카테고리: 우리회사가 배출한 폐기물을 다른 소각장이나 매립장에서 처리하는 과정에서 발생되는 탄소 배출량
... A96: 15. 카테고리: 우리회사가 다른 회사의 지분 참여등을 통해 투자한다면 해당 기업의 배출량

Sheet 탄소배출량 계산근거자료 2024년
A4: 2024년 배출량 계산
A7: 구분 | B7: 사용량 | C7: 온실가스배출량 (tco2/Kmw) | D7: 금액 | E7: scope | F7: 비고
A8: 전기 | B8: 448,582 KW | C8: 206.079 | D8: 84510970 | E8: scope2 | F8: 연간 전기 사용량(고지서)
A9: 가스사용량 | B9: 24,899 mJ | D9: 21708790 | E9: scope2 | F9: 연간 가스사용량(고지서)
A10: 상하수도사용량 | B10: 948 ton | D10: 1604720 | E10: scope2 | F10: 연간 상하수도사용량(고지서)
A12: 종량제 봉투 사용량 | B12: 4125 리터(75리터 X 55개) | F12: 연간 총 사용량
A13: 음식물 쓰레기 사용량 | B13: 외부급식으로 전환(23년_1,200kg) | F13: 연간 총 사용량
A14: 폐기물 마대사용량 | B14: 55개 | F14: 연간 총 사용량
A15: 연간유해 폐기물량 | B15: 2,630 KG | F15: 업체 자료기준
A17: 연간 제품 운송 배출량 | B17: 14,691 리터 | C17: 38.201 | D17: 22860635 | E17: scope3 | F17: 연간 주유량(법인 차량2대)
A18: 출퇴근 시 소요 배출량 | B18: 12,850 리터 | C18: 33.414 | D18: 19100000 | E18: scope3 | F18: 전 직원 출퇴근거리 연간 주유량
A21: * 참고 자료
A23: 1. 에너지 온실 가스 종합정보 플랫폼
A24: https://tips.energy.or.kr/popup/toe.do
A70: 2. SCOPE3 측정 가이드 북 참고
A75: * Scope 3
A77: [ 원자재 입고전]
A78: 1. 카테고리: 원자재의 탄소 배출량
A79: 2. 카테고리: 생산에 사용되는 설비, 장비의 탄소배출량
A80: 3. 카테고리: 회사운영에 사용되는 연료를 채굴하고 운반하고 정제되는 과정에서 발생되는 탄소배출량
A81: 4. 카테고리: 우리회사에 필요한 원자재와 설비를 다른 회사에서 운송되는 과정에서 발생되는 탄소배출량
A83: [ 생산공정]
A84: 5. 카테고리: 우리회사가 배출한 폐기물을 다른 소각장이나 매립장에서 처리하는 과정에서 발생되는 탄소 배출량
... A96: 15. 카테고리: 우리회사가 다른 회사의 지분 참여등을 통해 투자한다면 해당 기업의 배출량

Sheet Information
A1: Guideline
A3: A. Survey Criteria
B4: Reporting Period | D4: 2023
B5: Standards/Protocol | D5: The survey is following the Corporate Value Chain(Scope 3) Standard of Greenhouse Gas Protocol. It is based on the Scope 3 Calculation Guidance of Greenhouse Gas Protocol.
B6: Factories and Products | D6: Products supplied to Samsung Biologics during the reporting period. The entire factories producing products supplied to Samsung Biologics.
B7: Methodology | D7: Fill in according to the order of operation, "Required" items must be filled out, and "Required (some exceptions)" may not be filled out if the exception conditions apply. "Select" is written if relevant, or "None" if not relevant
A9: B. Survey Process
F18: Scope 1, 2, 3 Emissions
F21: Factory information & percentage of products supplied to SBL
D26: * Scope 3 emissions allocated to the production of products supplied to Samsung Biologics
L37: Product information & weight of the product & PCF
J42: * PCF: Product Carbon Footprint
Q47: Energy, Water, Waste, Materals & Substances of the product
A70: C. Criteria by the cell color
D71: Numerical or text data entry
D72: Select from drop-down list
D73: Automatic calculation (no creation or selection required)
D74: Not Applicable (No need to create)
C76: Product Name * | D76: The red asterisked column is a must-fill.

Sheet Summary
A1: Summary | I1: ※ Criteria by the cell color
A2: ※ Key data aggregation sheet of each sheet | J2: Numerical or text data entry
J3: Select from drop-down list
A4: 1. GHG(Greenhouse Gas) emissions | F4: * Performance year: the previous year | J4: Automatic calculation (no creation or selection required)
C5: unit | D5: Base year of Net zero target | F5: Reporting year | J5: Not Applicable (No need to create)
D6: Entire emissions | E6: Allocation to SBL | F6: Entire emissions | G6: Allocation to SBL
A7: Year | C7: year | D7: =Management!B21 -> 0 | F7: 2023 | I7: Product Name * | J7: The red asterisked column is a must-fill.
A8: Total GHG emissions | C8: tCO2eq/year | D8: =Emissions!D5 -> 260 | E8: =Emissions!D27 -> 24.84 | F8: =Emissions!E5 -> 276 | G8: =Emissions!E27 -> 24.84
A9: Scope 1 emissions | C9: tCO2eq/year | D9: =Emissions!D6 -> 0 | E9: =Emissions!D28 -> 0 | F9: =Emissions!E6 -> 0 | G9: =Emissions!E28 -> 0
A10: Scope 2 emissions | C10: tCO2eq/year | D10: =Emissions!D7 -> 195 | E10: =Emissions!D29 -> 18 | F10: =Emissions!E7 -> 200 | G10: =Emissions!E29 -> 18
A11: Scope 3 emissions | B11: Total | C11: tCO2eq/year | D11: =Emissions!D8 -> 65 | E11: =Emissions!D30 -> 6.84 | F11: =Emissions!E8 -> 76 | G11: =Emissions!E30 -> 6.84
B12: Category 1 | C12: tCO2eq/year | D12: =Emissions!D9 -> 0 | E12: =Emissions!D31 -> 0 | F12: =Emissions!E9 -> 0 | G12: =Emissions!E31 -> 0
B13: Category 4 | C13: tCO2eq/year | D13: =Emissions!D10 -> 0 | E13: =Emissions!D32 -> 0 | F13: =Emissions!E10 -> 0 | G13: =Emissions!E32 -> 0
B14: Category 9 | C14: tCO2eq/year | D14: =Emissions!D11 -> 0 | E14: =Emissions!D33 -> 0 | F14: =Emissions!E11 -> 0 | G14: =Emissions!E33 -> 0
A16: 2. Status of GHG emission management by product unit
C17: unit | D17: Reporting year
D18: Allocation to SBL
A19: Number of managed products | C19: number | D19: =COUNTA(Product!B5:B200) -> 19
A20: Number of external authentication products | C20: number | D20: =COUNTIF(Product!J:J,"Yes") -> 0
A22: 3. Details of GHG emissions
C23: unit | D23: Reporting year | E23: Sheet name | F23: Note
D24: Allocation to SBL
A25: Emissions from product transportation | C25: tCO2eq/year | D25: =Emissions!E39 -> 3.69 | E25: Emissions | F25: Scope 3
A26: Emissions from energy use | C26: tCO2eq/year | D26: =SUMIFS(Hybrid!J:J,Hybrid!B:B,"Energy") -> 0 | E26: Hybrid | F26: Scope 1, 2
A27: Emissions from waste disposal | C27: tCO2eq/year | D27: =SUMIFS(Hybrid!J:J,Hybrid!B:B,"Waste") -> 0 | E27: Hybrid | F27: Scope 3
A28: Emissions from raw material transportation | C28: tCO2eq/year | D28: =Emissions!E34 -> 0 | E28: Emissions | F28: Scope 3

Sheet Management
A1: Management | I1: ※ Criteria by the cell color
J2: Numerical or text data entry
A3: 1. GHG Emssions target | J3: Select from drop-down list
J4: Automatic calculation (no creation or selection required)
A5: 1.1 Do you have a GHG Emissions target? * | D5: No | J5: Not Applicable (No need to create)
A7: 1.2 (If yes) GHG Emissions target
A8: Scope * | B8: Base year * | C8: Target year * | D8: Emissions of the base year * (tonCO2eq/year) | E8: Emissions of target year * (tonCO2eq/year) | F8: SBTi Validation? *
A9: Scope 1+2 | B9: 2023 | C9: 2025 | D9: 200 | E9: 195 | F9: No plan
A10: Scope 3 | B10: 2023 | C10: 2025 | D10: 41.012 | E10: 35 | F10: No plan
A13: 1.3 (If No) Do you have any plans to establish a GHG Emissions target? * | E13: In 2 years
A15: 2. Net zero target
A17: 2.1 Do you have a Net zero target? * | D17: No
A19: 2.2 (If yes) Net zero target
A20: Scope * | B20: Base year * | C20: Target year * | D20: Emissions of the base year * (tonCO2eq/year) | E20: Emissions in 2030 * (tonCO2eq/year) | F20: Emissions in 2040 * (tonCO2eq/year) | G20: Emissions in 2050 * (tonCO2eq/year) | H20: SBTi Validation? *
A25: 1.3 (If No) Do you have any plans to establish a Net zero target? * | E25: Not yet
A27: 3. RE100 Target
A29: 3.1 Do you have a RE100 target? * | D29: No
A31: 3.2 (If yes) RE100 target
A32: Type * | B32: Join year * | C32: Base year * | D32: Target year * | E32: % of renewable power used in the base year * | F32: % of renewable power used in 2030 * | G32: % of renewable power used in 2040 * | H32: % of renewable power used in 2050 * | I32: * % = Renewable power used / total electricity consumption * 100
A33: Renewable power
A35: 1.3 (If No) Do you have any plans to join in RE100? * | D35: Not yet

Sheet Emissions
A1: GHG Emissions
A3: 1. Emissions for the production
A4: Scope | B4: Category | C4: Relevent & Calculation * | D4: Base year of Target * (tCO2eq/year) | E4: Reporting year(Y 2023) * (tCO2eq/year) | F4: 3rd party verification of reporting year emissions * | G4: Representative Calculation method * (Scope 3) | I4: [Note]
A5: Total | D5: =D6+D7+D8 -> 260 | E5: =E6+E7+E8 -> 276 | I5: 1. Scope 3 Category (For more information: https://ghgprotocol.org/scope-3-calculation-guidance-2)
A6: Scope 1 | B6: Total | C6: No and not calculated | F6: Not verified | I6: - Category 1: Extraction, production, and transportation of goods and services purchased or acquired by the reporting company in the reporting year.
A7: Scope 2 | B7: Total | C7: Yes and calculated | D7: 195 | E7: 200 | F7: Not verified | I7: - Category 2: Extraction, production, and transportation of capital goods purchased or acquired by the reporting company in the reporting year.
A8: Scope 3 | B8: Total | D8: =SUM(D9:D23) -> 65 | E8: =SUM(E9:E23) -> 76 | I8: - Category 3: Extraction, production, and transportation of fuels and energy purchased or acquired by the reporting company in the reporting year, not already accounted for in scope 1 or scope 2.
B9: Catergory 1 | C9: No and not calculated | I9: - Category 4: Transportation and distribution of products purchased by the reporting company in the reporting year between a company’s tier 1 suppliers and its own operations (in vehicles nd facilities not owned or controlled by the reporting company). Transportation and distribution services purchased by the reporting company in the reporting year, including inbound logistics, outbound logistics (e.g., of sold products), and transportation and distribution between a company’s own facilities (in vehicles and facilities not owned or controlled by the reporting company)
B10: Catergory 2 | C10: No and not calculated | I10: - Category 5: Disposal and treatment of waste generated in the reporting company’s operations in the reporting year (in facilities not owned or controlled by the reporting company)
B11: Catergory 3 | C11: No and not calculated | I11: - Category 6: Transportation of employees for business-related activities during the reporting year (in vehicles not owned or operated by the reporting company)
B12: Catergory 4 | C12: No and not calculated | I12: - Category 7: Transportation of employees between their homes and their worksites during the reporting year (in vehicles not owned or operated by the reporting company)
B13: Catergory 5 | C13: No and not calculated | I13: - Category 8: Operation of assets leased by the reporting company (lessee) in the reporting year and not included in scope 1 and scope 2 – reported by lessee
B14: Catergory 6 | C14: No and not calculated | I14: - Category 9: Transportation and distribution of products sold by the reporting company in the reporting year between the reporting company’s operations and the end consumer (if not paid for by the reporting company), including retail and storage (in vehicles and facilities not owned or controlled by the reporting company)
B15: Catergory 7 | C15: Yes and calculated | D15: 30 | E15: 35 | F15: Not verified | G15: Distance-based method | I15: - Category 10: Processing of intermediate products sold in the reporting year by downstream companies (e.g., manufacturers)
B16: Catergory 8 | C16: No and not calculated | I16: - Category 11: End use of goods and services sold by the reporting company in the reporting year
B17: Catergory 9 | C17: Yes and calculated | D17: 35 | E17: 41 | F17: Not verified | G17: Transportation: Spend-based data method / Distribution: Average-data method | I17: - Category 12: Waste disposal and treatment of products sold by the reporting company (in the reporting year) at the end of their life
B18: Catergory 10 | C18: No and not calculated | I18: - Category 13: Operation of assets owned by the reporting company (lessor) and leased to other entities in the reporting year, not included in scope 1 and scope 2 – reported by lessor
B19: Catergory 11 | C19: No and not calculated | I19: - Category 14: Operation of franchises in the reporting year, not included in scope 1 and scope 2 – reported by franchisor
B20: Catergory 12 | C20: No and not calculated | I20: - Category 15: Operation of investments (including equity and debt investments and project finance) in the reporting year, not included in scope 1 or scope 2
B21: Catergory 13 | C21: No and not calculated | I21: ※ Criteria by the cell color
B22: Catergory 14 | C22: No and not calculated | J22: Numerical or text data entry
B23: Catergory 15 | C23: No and not calculated | J23: Select from drop-down list
J24: Automatic calculation (no creation or selection required)
A25: 2. Emissions for the production of products supplied to SBL | J25: Not Applicable (No need to create)
A26: Scope | B26: Category | C26: % of total emissions due to SBL products * (Reporting year) | D26: Base year of Target * (tCO2eq/year) | E26: Reporting year(Y 2023) * (tCO2eq/year) | F26: A description of what percentage of total emissions are due to products supplied to the SBL. *
A27: Total | D27: =D28+D29+D30 -> 24.84 | E27: =E28+E29+E30 -> 24.84
A28: Scope 1 | B28: Total | E28: =$C28*E6 -> 0
A29: Scope 2 | B29: Total | C29: 0.09 | D29: =E7*C29 -> 18 | E29: =$C29*E7 -> 18 | F29: Ratio to total sales
A30: Scope 3 | B30: Total | D30: =SUM(D31:D45) -> 6.84 | E30: =SUM(E31:E45) -> 6.84
B31: Catergory 1 | E31: =$C31*E9 -> 0
B32: Catergory 2 | E32: =$C32*E10 -> 0
B33: Catergory 3 | E33: =$C33*E11 -> 0
B34: Catergory 4 | E34: =$C34*E12 -> 0
B35: Catergory 5 | E35: =$C35*E13 -> 0
B36: Catergory 6 | E36: =$C36*E14 -> 0
B37: Catergory 7 | C37: 0.09 | D37: =E15*C37 -> 3.15 | E37: =$C37*E15 -> 3.15 | F37: Ratio to total sales
B38: Catergory 8 | E38: =$C38*E16 -> 0
B39: Catergory 9 | C39: 0.09 | D39: =E17*C39 -> 3.69 | E39: =$C39*E17 -> 3.69 | F39: Ratio to total sales
B40: Catergory 10 | E40: =$C40*E18 -> 0
B41: Catergory 11 | E41: =$C41*E19 -> 0
...

Sheet Factory
A1: Manufacturing factory
A3: 1. Manufacturing factory
A4: No | B4: Name of the factory * | C4: Country * | D4: City * | E4: Address * | F4: Major manufacturing products for SBL * | G4: Percentages of the supplied products to SBL out of total production of this factory * (%) | H4: Percentages of the supplied products to SBL from this factory out of total supplied products to SBL from your company * (%) | I4: Description of the rationale for percentages of the supplied products to SBL *
A5: 1 | B5: SAMHWADANG P&T | C5: South Korea | D5: Gyeonggi-do | E5: 39, Jingwansandan-ro 59beon-gil, Jingeon-eup, Namyangju-si, Gyeonggi-do | F5: CARTON DIVIDER, CARTON FLLER, LABEL_VIAL PRODUCT.., | G5: 0.09 | H5: 1 | I5: Ratio to total sales | L5: Numerical or text data entry
A6: 2 | L6: Select from drop-down list
A7: 3 | L7: Automatic calculation (no creation or selection required)
A8: 4 | L8: Not Applicable (No need to create)
A9: 5
A10: 6
A11: 7
A12: 8
A13: 9
A14: 10

Sheet Product
A1: Product Carbon Footprints
A3: 1. Product carbon footprints
A4: No | B4: Product Name * | C4: Product code(Vendor) | D4: Product code(SBL) * | E4: Product Type 1 * | F4: Product Type 2 * | G4: Supply Unit * | H4: Weight conversion factor * (g/Supply Unit) | I4: Product Carbon Footprint (gCO2eq/kg) | J4: Whether the PCF is validated by the 3rd party
A5: 1 | B5: CARTON BOX_PE16BD | C5: 55-022 | D5: 1001942 | E5: Paper_products | F5: Paper bag and coated and treated paper manufacturing | G5: EA | H5: 12.4 | I5: N/A | J5: No | M5: Numerical or text data entry
A6: 2 | B6: LABEL_VIAL_PRODUCT_PE16BD | C6: 55-021 | D6: 1001941 | E6: Plastics_rubber_prods | F6: Plastics packaging materials and unlaminated film and sheet manufacturing | G6: EA | H6: 0.3 | I6: N/A | J6: No | M6: Select from drop-down list
A7: 3 | B7: CARTON DIVIDER_PE16A | C7: 55-003 | D7: 1001574 | E7: Paper_products | F7: Paper bag and coated and treated paper manufacturing | G7: EA | H7: 10.5 | I7: N/A | J7: No | M7: Automatic calculation (no creation or selection required)
A8: 4 | B8: SHIPPING BOX_PE16B | C8: 55-004 | D8: 1001866 | E8: Paper_products | F8: Paper bag and coated and treated paper manufacturing | G8: EA | H8: 26 | I8: N/A | J8: No | M8: Not Applicable (No need to create)
A9: 5 | B9: TAMPER STICKER_CARTON_PE16A | C9: 55-011 | D9: 1001575 | E9: Paper_products | F9: Paper bag and coated and treated paper manufacturing | G9: EA | H9: 2 | I9: N/A | J9: No
A10: 6 | B10: CARTON BOX_PE16 | C10: 65-002 | D10: 1001998 | E10: Paper_products | F10: Paper bag and coated and treated paper manufacturing | G10: EA | H10: 9.9 | I10: N/A | J10: No | L10: * Product code(SBL) : 7-digit SBL material code starting with 1 or 9
A11: 7 | B11: CARTON FILLER_PE16 | C11: 65-005 | D11: 1001997 | E11: Paper_products | F11: Paper bag and coated and treated paper manufacturing | G11: EA | H11: 8.4 | I11: N/A | J11: No | L11: Required to link products from suppliers to materials in the SBL.
A12: 8 | B12: CARTON DIVIDER_PE16 | C12: 65-003 | D12: 1001999 | E12: Paper_products | F12: Paper bag and coated and treated paper manufacturing | G12: EA | H12: 4 | I12: N/A | J12: No
A13: 9 | B13: SHIPPING BOX_PE16 | C13: 65-004 | D13: 1002000 | E13: Paper_products | F13: Paper bag and coated and treated paper manufacturing | G13: EA | H13: 27 | I13: N/A | J13: No
A14: 10 | B14: CARTON BOX_PE16 | C14: 65-001 | D14: 1001998 | E14: Paper_products | F14: Paper bag and coated and treated paper manufacturing | G14: EA | H14: 0.2 | I14: N/A | J14: No
A15: 11 | B15: LABEL_VIAL_PRODUCT_PE16BF | C15: 65-006 | D15: 1002116 | E15: Plastics_rubber_prods | F15: Plastics packaging materials and unlaminated film and sheet manufacturing | G15: EA | H15: 0.2 | I15: N/A | J15: No
A16: 12 | B16: LABEL_VIAL_PRODUCT_PE16AC | C16: 65-009 | D16: 1002117 | E16: Plastics_rubber_prods | F16: Plastics packaging materials and unlaminated film and sheet manufacturing | G16: EA | H16: 0.2 | I16: N/A | J16: No
A17: 13 | B17: CARTON BOX_PE16BF | C17: 65-007 | D17: 100218 | E17: Paper_products | F17: Paper bag and coated and treated paper manufacturing | G17: EA | H17: 8.3 | I17: N/A | J17: No
A18: 14 | B18: CARTON BOX_PE16AC | C18: 65-010 | D18: 1002132 | E18: Paper_products | F18: Paper bag and coated and treated paper manufacturing | G18: EA | H18: 8.1 | I18: N/A | J18: No
A19: 15 | B19: CARTON DIVIDER_2R_PE16B | C19: 65-011 | D19: 1002119 | E19: Paper_products | F19: Paper bag and coated and treated paper manufacturing | G19: EA | H19: 3.1 | I19: N/A | J19: No
A20: 16 | B20: CARTON FILLER_2R_PE16B | C20: 65-012 | D20: 1002120 | E20: Paper_products | F20: Paper bag and coated and treated paper manufacturing | G20: EA | H20: 2.7 | I20: N/A | J20: No
A21: 17 | B21: SHIPPING BOX_2R_PE16B | C21: 65-008 | D21: 1002121 | E21: Paper_products | F21: Paper bag and coated and treated paper manufacturing | G21: EA | H21: 30 | I21: N/A | J21: No
A22: 18 | B22: LABEL_VIAL_PRODUCT_PE16AD | C22: 65-013 | D22: 1002176 | E22: Plastics_rubber_prods | F22: Plastics packaging materials and unlaminated film and sheet manufacturing | G22: EA | H22: 0.2 | I22: N/A | J22: No
A23: 19 | B23: CARTON_BOX_PE16AD | C23: 65-014 | D23: 1002174 | E23: Paper_products | F23: Paper bag and coated and treated paper manufacturing | G23: EA | H23: 8 | I23: N/A | J23: No
A24: 20
A25: 21
A26: 22
A27: 23
A28: 24
A29: 25
A30: 26
A31: 27
A32: 28
A33: 29
A34: 30
A35: 31
... A304: 300

Sheet Hybrid
A1: Data for Calculating Total Product Carbon Footprints
A3: 1. Energy Consumption | E3: If necessary, add a line below the last line to complete the following
A4: No | B4: Type | C4: Energy Type | D4: Use/Not use * | E4: Energy usage for the reporting year * | F4: Unit (Do not change units) | G4: SBL's portion (%) * | H4: Scope of GHG emission * | I4: GHG emission factor (Scope 1 or 2) (tonCO2eq/unit) | J4: GHG emissions for SBL * (tCO2eq/year) | K4: Note * (Description about the percentage related to SBL)
A5: 1 | B5: Energy | C5: LNG | D5: Use | E5: 20 | F5: MJ | G5: 0.09 | H5: Scope 2 | J5: =E5*G5*I5 -> 0 | K5: Ratio to total sales | N5: Numerical or text data entry
A6: 2 | B6: Energy | C6: LPG | D6: Not use | F6: MJ | J6: =E6*G6*I6 -> 0 | N6: Select from drop-down list
A7: 3 | B7: Energy | C7: Disel | D7: Not use | F7: MJ | J7: =E7*G7*I7 -> 0 | N7: Automatic calculation (no creation or selection required)
A8: 4 | B8: Energy | C8: B-C Oil | D8: Not use | F8: MJ | J8: =E8*G8*I8 -> 0 | N8: Not Applicable (No need to create)
A9: 5 | B9: Energy | C9: B-A Oil | D9: Not use | F9: MJ | J9: =E9*G9*I9 -> 0
A10: 6 | B10: Energy | C10: Bio Gas | D10: Not use | F10: MJ | J10: =E10*G10*I10 -> 0 | M10: * Product code(SBL) : 7-digit SBL material code starting with 1 or 9
A11: 7 | B11: Energy | C11: Bio Oil | D11: Not use | F11: MJ | J11: =E11*G11*I11 -> 0 | M11: Required to link products from suppliers to materials in the SBL.
A12: 8 | B12: Energy | C12: Bio mass | D12: Not use | F12: MJ | J12: =E12*G12*I12 -> 0
A13: 9 | B13: Energy | C13: Renewable electricity | D13: Not use | F13: MWh | J13: =E13*G13*I13 -> 0
A14: 10 | B14: Energy | C14: Non-renewable electricity | D14: Use | E14: 450 | F14: MWh | G14: 0.09 | H14: Scope 2 | J14: =E14*G14*I14 -> 0 | K14: Ratio to total sales
A15: 11 | B15: Energy | C15: Hot water or Steam from renewable sources | D15: Not use | F15: MJ | J15: =E15*G15*I15 -> 0
A16: 12 | B16: Energy | C16: Hot water or Steam from non-renewable sources | D16: Not use | F16: MJ | J16: =E16*G16*I16 -> 0
A17: 13 | B17: Energy | C17: Other(direct entry) | D17: Not use | F17: MJ | J17: =E17*G17*I17 -> 0
A18: 14 | B18: Energy | C18: Other(direct entry) | D18: Not use | F18: MJ | J18: =E18*G18*I18 -> 0
A19: 15 | B19: Energy | C19: Other(direct entry) | D19: Not use | F19: MJ | J19: =E19*G19*I19 -> 0
A21: 2. Water Usage
A22: No | B22: Type | C22: Water Type | D22: Use/Not use * | E22: Water usage for the reporting year * | F22: Unit (Do not change units) | G22: SBL's portion (%) * | I22: Life cycle climate change impact * (kgCO2eq/ton) | J22: GHG emissions for SBL * (tCO2eq/year) | K22: Note * (Description about the percentage related to SBL)
A23: 1 | B23: Water | C23: Industrial water | D23: Not use | F23: ton | J23: =E23*G23*I23/1000 -> 0
A24: 2 | B24: Water | C24: Domestic water | D24: Use | E24: 900 | F24: ton | G24: 0.09 | J24: =E24*G24*I24/1000 -> 0 | K24: Ratio to total sales
A25: 3 | B25: Water | C25: Groundwater | D25: Not use | F25: ton | J25: =E25*G25*I25/1000 -> 0
A26: 4 | B26: Water | C26: Recycling water | D26: Not use | F26: ton | J26: =E26*G26*I26/1000 -> 0
A27: 5 | B27: Water | C27: Rain water | D27: Not use | F27: ton | J27: =E27*G27*I27/1000 -> 0
A29: 3. Waste Disposal | E29: If necessary, add a line below the last line to complete the following
A30: No | B30: Type | C30: Disposal method - Waste type | D30: Dispose /Not dispose * | E30: Waste disposal volume for the reporting year * | F30: Unit (Do not change units) | G30: SBL's portion (%) * | I30: Life cycle climate change impact * (kgCO2eq/kg) | J30: GHG emissions for SBL * (tCO2eq/year) | K30: Note * (Description about the percentage related to SBL)
A31: 1 | B31: Waste | C31: Landfill-General(household) waste | D31: Not dispose | F31: kg | J31: =E31*G31*I31/1000 -> 0
A32: 2 | B32: Waste | C32: Landfill-Organic waste (Food waste, etc.) | D32: Dispose | E32: 4500 | F32: kg | G32: 0.09 | J32: 0 | K32: Ratio to total sales
A33: 3 | B33: Waste | C33: Landfill-Hazardous waste | D33: Dispose | E33: 4120 | F33: kg | J33: =E33*G32*I33/1000 -> 0 | K33: Ratio to total sales
A34: 4 | B34: Waste | C34: Landfill-Waste rubber/waste leather | D34: Not dispose | F34: kg | J34: =E34*G34*I34/1000 -> 0
A35: 5 | B35: Waste | C35: Landfill-Waste metals | D35: Not dispose | F35: kg | J35: =E35*G35*I35/1000 -> 0
A36: 6 | B36: Waste | C36: Landfill-Waste wood | D36: Not dispose | F36: kg | J36: =E36*G36*I36/1000 -> 0
A37: 7 | B37: Waste | C37: Landfill-Waste glass | D37: Not dispose | F37: kg | J37: =E37*G37*I37/1000 -> 0
A38: 8 | B38: Waste | C38: Landfill-Waste paper | D38: Not dispose | F38: kg | J38: =E38*G38*I38/1000 -> 0
A39: 9 | B39: Waste | C39: Landfill-Waste concrete(construction waste) | D39: Not dispose | F39: kg | J39: =E39*G39*I39/1000 -> 0
A40: 10 | B40: Waste | C40: Landfill-Mixed waste plastic | D40: Not dispose | F40: kg | J40: =E40*G40*I40/1000 -> 0
A41: 11 | B41: Waste | C41: Incineration-General(household) waste | D41: Not dispose | F41: kg | J41: =E41*G41*I41/1000 -> 0
A42: 12 | B42: Waste | C42: Incineration-Organic waste | D42: Not dispose | F42: kg | J42: =E42*G42*I42/1000 -> 0
A43: 13 | B43: Waste | C43: Incineration-Hazardous waste | D43: Not dispose | F43: kg | J43: =E43*G43*I43/1000 -> 0
...

Sheet Ref)EEIO
A1: Selection options : USEEIO Commodities
A3: Category 1 | B3: Category 2 | D3: Category 1
A4: Farms | B4: Animal production, except cattle and poultry and eggs | D4: Alcoholic_beverages
A5: Farms | B5: Beef cattle ranching and farming, including feedlots and dual-purpose ranching and farming | D5: Animal_food_mfg
A6: Farms | B6: Dairy cattle and milk production | D6: Animal_slaughtering_proc
A7: Farms | B7: Fruit and tree nut farming | D7: Bakeries_tortilla_mfg
A8: Farms | B8: Grain farming | D8: Chemical_prods
A9: Farms | B9: Greenhouse, nursery, and floriculture production | D9: Computer_and_electronic_product_mfg
A10: Farms | B10: Oilseed farming | D10: Construction
A11: Farms | B11: Other crop farming | D11: Dairy_prods
A12: Farms | B12: Poultry and egg production | D12: Electrical_equipment_appliance_and_component_mfg
A13: Farms | B13: Support activities for agriculture and forestry | D13: Electricity
A14: Farms | B14: Vegetable and melon farming | D14: Fabricated_metal_product_mfg
... A38: Dairy prods | B38: Dry, condensed, and evaporated dairy product manufacturing | D38: Wood_prods
A39: Dairy prods | B39: Fluid milk and butter manufacturing
A40: Dairy prods | B40: Ice cream and frozen dessert manufacturing
A41: Fruit & Vegetable preserving | B41: Frozen food manufacturing
A42: Fruit & Vegetable preserving | B42: Fruit and vegetable canning, pickling, and drying
A43: Grain & oilseed milling | B43: Breakfast cereal manufacturing
A44: Grain & oilseed milling | B44: Fats and oils refining and blending
A45: Grain & oilseed milling | B45: Flour milling and malt manufacturing
A46: Grain & oilseed milling | B46: Soybean and other oilseed processing
A47: Grain & oilseed milling | B47: Wet corn milling
A48: Other food mfg | B48: All other food manufacturing
A49: Other food mfg | B49: Coffee and tea manufacturing
A50: Other food mfg | B50: Flavoring syrup and concentrate manufacturing
... A272: Oil & gas extraction | B272: Oil and gas extraction

Sheet Ref
A2: Unit 1 | B2: EA
B3: BOT
B4: BOX
B5: CS
B6: DR
B7: g
B8: GAL
B9: kg
B10: L
B11: LB
B12: ML
B13: PAI
B14: PAK
... B18: Other
A19: Allocation | B19: Product production quantity based
B20: Product sales based
B21: Production uptime based
B22: Measurement through the system
B23: Others (Describe on the Description section)
A24: Energy Type | B24: LNG
B25: LPG
B26: Disel
B27: B-C Oil
B28: B-A Oil
B29: Bio Gas
B30: Bio Oil
B31: Bio mass
B32: Renewable electricity
B33: Non-renewable electricity
B34: Hot water or Steam from renewable sources
B35: Hot water or Steam from non-renewable sources
B36: Others (Describe on the Description section)
A37: Unit 2 | B37: kg
B38: ton
B39: L
B40: kL
B41: Nm3
B42: thousand Nm3
B43: kWh
B44: MWh
...
